<?xml version="1.0"?>

<robot name="iai_dish_washer" xmlns:xacro="http://ros.org/wiki/xacro">

  <xacro:property name="pi" value="3.1415926535897931" />

  <xacro:macro name="iai_dish_washer" params="name parent *origin">
     <link name="${name}_main">

      <xacro:sphere_inertia radius="0" mass="0"/>
      <visual>
        <origin xyz="0 0 0" rpy="0 0 0" />
        <geometry>
          <mesh filename="package://iai_kitchen/meshes/misc/DishWasher.dae"/>
        </geometry>
      </visual>
      <collision>
        <origin xyz="0 0 0" rpy="0 0 0" />
        <geometry>
          <mesh filename="package://iai_kitchen/meshes/misc/DishWasher.obj"/>
        </geometry>
      </collision>
    </link>

    <link name="${name}_door">

      <xacro:sphere_inertia radius="0" mass="0"/>
      <visual>
        <origin xyz="0 0.055 0" rpy="${0.5*pi} 0 0" />
        <geometry>
          <mesh filename="package://iai_kitchen/meshes/misc/DishWasherDoor.dae"/>
        </geometry>
      </visual>
      <collision>
        <origin xyz="0 0.055 0" rpy="${0.5*pi} 0 0" />
        <geometry>
          <mesh filename="package://iai_kitchen/meshes/misc/DishWasherDoor.obj"/>
        </geometry>
      </collision>
    </link>

    <link name="${name}_door_handle">
      <xacro:sphere_inertia radius="0" mass="0"/>
      <visual>
        <origin xyz="0 0 0" rpy="0 0 0" />
        <geometry>
          <mesh filename="package://iai_kitchen/meshes/handles/Handle60.dae"/>
        </geometry>
      </visual>
      <collision>
        <origin xyz="0 0 0" rpy="0 0 0" />
        <geometry>
          <mesh filename="package://iai_kitchen/meshes/handles/Handle60.obj"/>
        </geometry>
      </collision>
    </link>
    <!--
    <xacro:if value="simulated"/>
    -->
    <joint name="${name}_main_joint" type="fixed">
      <xacro:insert_block name="origin" />
      <parent link="${parent}"/>
      <child link="${name}_main"/>
    </joint>

    <!--
    <xacro:if value="${simulated}">
    <joint name="${name}_door_joint" type="revolute">
      <origin xyz="0.27 0. -0.325" rpy="${-0.5*pi} 0 0" />
      <parent link="${name}_main"/>
      <child link="${name}_door"/>
      <axis xyz="0 0 1"/>
       FIXME make closed position stable instead of forbidding opening...
      <limit lower="0" upper="0" effort="300" velocity="10"/>
    </joint>

    </xacro:if>
    -->
    <!--
    <xacro:unless value="${simulated}">
    -->
    <joint name="${name}_door_joint" type="revolute">
      <origin xyz="0.27 0. -0.285" rpy="${-0.5*pi} 0 0" />
      <parent link="${name}_main"/>
      <child link="${name}_door"/>
      <axis xyz="0 0 1"/>
      <!--
      <limit lower="0" upper="${0.5*pi}" effort="300" velocity="10"/>
      -->
      <limit lower="0" upper="${0.5*pi}" effort="300" velocity="10"/>
    </joint>
    <!--
    </xacro:unless>
  -->
    <joint name="${name}_door_handle_joint" type="fixed">
      <origin xyz="0.085 -0.575 0.0" rpy="${-0.5*pi} 0 0" />
      <parent link="${name}_door"/>
      <child link="${name}_door_handle"/>
    </joint>

    <xacro:dishwasher_tray name="${name}_tray" parent="${name}_main">
      <origin xyz="-0.08 0 0.15"/>
    </xacro:dishwasher_tray>

  </xacro:macro>

  <xacro:macro name="dishwasher_tray" params="name parent *origin">

    <joint name="${name}_main" type="prismatic">
      <xacro:insert_block name="origin"/>
      <parent link="${parent}"/>
      <child link="${name}_bottom"/>
      <axis xyz="1 0 0"/>
      <limit lower="0" upper="0.48" effort="300" velocity="10"/>
    </joint>


    <link name="${name}_bottom">
      <visual>
        <geometry>
          <box size="0.32 0.5 0.05"/>
        </geometry>
      </visual>
      <collision>
        <geometry>
          <box size="0.32 0.5 0.05"/>
        </geometry>
      </collision>
    </link>

    <link name="${name}_left_side">
      <visual>
        <geometry>
          <box size="0.32 0.005 0.17"/>
        </geometry>
      </visual>
      <collision>
        <geometry>
          <box size="0.32 0.005 0.17"/>
        </geometry>
      </collision>
    </link>

    <link name="${name}_right_side">
      <visual>
        <geometry>
          <box size="0.32 0.005 0.17"/>
        </geometry>
      </visual>
      <collision>
        <geometry>
          <box size="0.32 0.005 0.17"/>
        </geometry>
      </collision>
    </link>

    <link name="${name}_back_side">
      <visual>
        <geometry>
          <box size="0.005 0.5 0.17"/>
        </geometry>
      </visual>
      <collision>
        <geometry>
          <box size="0.005 0.5 0.17"/>
        </geometry>
      </collision>
    </link>

    <link name="${name}_front_side">
      <visual>
        <geometry>
          <box size="0.005 0.5 0.17"/>
        </geometry>
      </visual>
      <collision>
        <geometry>
          <box size="0.005 0.5 0.17"/>
        </geometry>
      </collision>
    </link>

    <joint name="${name}_bottom_left" type="fixed">
      <origin xyz="-0.0 -0.25 0.075"/>
      <child link="${name}_left_side" />
      <parent link="${name}_bottom"/>
    </joint>

    <joint name="${name}_bottom_right" type="fixed">
      <origin xyz="-0.0 0.25 0.075"/>
      <child link="${name}_right_side" />
      <parent link="${name}_bottom"/>
    </joint>

    <joint name="${name}_bottom_back" type="fixed">
      <origin xyz="-0.16 0 0.075"/>
      <child link="${name}_back_side" />
      <parent link="${name}_bottom"/>
    </joint>

    <joint name="${name}_bottom_front" type="fixed">
      <origin xyz="0.16 0 0.075"/>
      <child link="${name}_front_side" />
      <parent link="${name}_bottom"/>
    </joint>

    <xacro:tray_handle name="${name}_handle" parent="${name}_front_side">
      <origin xyz="0.06 -0.1 -0.02"/>
    </xacro:tray_handle>

  </xacro:macro>

  <xacro:macro name="tray_handle" params="name parent *origin">

    <joint name="${name}_joint" type="fixed">
      <xacro:insert_block name="origin"/>
      <child link="${name}_front_side" />
      <parent link="${parent}"/>
    </joint>

    <link name="${name}_left_side">
      <visual>
        <geometry>
          <box size="0.03 0.01 0.01"/>
        </geometry>
      </visual>
      <collision>
        <geometry>
          <box size="0.03 0.01 0.01"/>
        </geometry>
      </collision>
    </link>

    <link name="${name}_right_side">
      <visual>
        <geometry>
          <box size="0.03 0.01 0.01"/>
        </geometry>
      </visual>
      <collision>
        <geometry>
          <box size="0.03 0.01 0.01"/>
        </geometry>
      </collision>
    </link>

    <link name="${name}_front_side">
      <visual>
        <geometry>
          <box size="0.01 0.2 0.01"/>
        </geometry>
      </visual>
      <collision>
        <geometry>
          <box size="0.01 0.2 0.01"/>
        </geometry>
      </collision>
    </link>

    <joint name="${name}_front_left_joint" type="fixed">
      <origin xyz="-0.01 -0.1 0"/>
      <child link="${name}_left_side" />
      <parent link="${name}_front_side"/>
    </joint>

    <joint name="${name}_front_right_joint" type="fixed">
      <origin xyz="-0.01 0.1 0"/>
      <child link="${name}_right_side" />
      <parent link="${name}_front_side"/>
    </joint>


  </xacro:macro>

</robot>
