<?xml version="1.0" ?>
<!-- =================================================================================== -->
<!-- |    This document was autogenerated by xacro from /home/giang/Workspace/map_ws/src/iai_maps/iai_apartment/urdf/apartment_unreal.xacro | -->
<!-- |    EDITING THIS FILE BY HAND IS NOT RECOMMENDED                                 | -->
<!-- =================================================================================== -->
<robot name="apartment">
  <link name="apartment_root">
    <origin rpy="0 0 0" xyz="0 0 0"/>
  </link>
  <joint name="furnitures_base" type="fixed">
    <origin xyz="8.85 1.75 0.0"/>
    <parent link="apartment_root"/>
    <child link="furnitures_root"/>
  </joint>
  <link name="furnitures_root"/>
  <!-- things and stuff -->
  <joint name="walls_joint" type="fixed">
    <origin rpy="0 0 0" xyz="0 0 -0.2"/>
    <parent link="furnitures_root"/>
    <child link="walls"/>
  </joint>
  <link name="walls">
    <visual>
      <geometry>
        <mesh filename="package://iai_apartment/meshes/visual/walls.dae"/>
      </geometry>
    </visual>
    <!--collision>
          <geometry>
            <mesh filename="package://iai_apartment/meshes/collision/walls.stl" />
          </geometry>
        </collision-->
  </link>
  <joint name="windows_joint" type="fixed">
    <origin rpy="0 0 0" xyz="0 0 -0.2"/>
    <parent link="furnitures_root"/>
    <child link="windows"/>
  </joint>
  <link name="windows">
    <visual>
      <geometry>
        <mesh filename="package://iai_apartment/meshes/visual/windows.dae"/>
      </geometry>
    </visual>
    <!--collision>
          <geometry>
            <mesh filename="package://iai_apartment/meshes/collision/windows.obj"/>
          </geometry>
        </collision-->
  </link>
  <!-- Collision okay Walls -->
  <!-- From the door side being wall 1, turn right and count the walls. -->
  <joint name="wall_coloksu_wall1_joint" type="fixed">
    <origin rpy="0 0 -1.57" xyz="0.6 -1.615 1.53"/>
    <parent link="furnitures_root"/>
    <child link="wall_coloksu_wall1"/>
  </joint>
  <link name="wall_coloksu_wall1">
    <collision>
      <origin rpy="0 1.57 0"/>
      <geometry>
        <box size="3.05 18.95 0.003"/>
      </geometry>
    </collision>
  </link>
  <joint name="wall_coloksu_wall2_joint" type="fixed">
    <origin rpy="0 0 3.14" xyz="-8.855 0.782 1.53"/>
    <parent link="furnitures_root"/>
    <child link="wall_coloksu_wall2"/>
  </joint>
  <link name="wall_coloksu_wall2">
    <collision>
      <origin rpy="0 1.57 0"/>
      <geometry>
        <box size="3.05 4.808 0.003"/>
      </geometry>
    </collision>
  </link>
  <joint name="wall_coloksu_wall3_joint" type="fixed">
    <origin rpy="0 0 1.57" xyz="0.6 3.180 1.53"/>
    <parent link="furnitures_root"/>
    <child link="wall_coloksu_wall3"/>
  </joint>
  <link name="wall_coloksu_wall3">
    <collision>
      <origin rpy="0 1.57 0"/>
      <geometry>
        <box size="3.05 18.95 0.003"/>
      </geometry>
    </collision>
  </link>
  <joint name="wall_coloksu_wall4_joint" type="fixed">
    <origin rpy="0 0 0" xyz="10.069 0.782 1.53"/>
    <parent link="furnitures_root"/>
    <child link="wall_coloksu_wall4"/>
  </joint>
  <link name="wall_coloksu_wall4">
    <collision>
      <origin rpy="0 1.57 0"/>
      <geometry>
        <box size="3.05 4.808 0.003"/>
      </geometry>
    </collision>
  </link>
  <joint name="wardrobe_joint" type="fixed">
    <origin rpy="0 0 0" xyz="9.7082 -0.6331 0.0"/>
    <parent link="furnitures_root"/>
    <child link="wardrobe"/>
  </joint>
  <link name="wardrobe">
    <visual>
      <geometry>
        <mesh filename="package://iai_apartment/meshes/visual/wardrobe.dae"/>
      </geometry>
    </visual>
    <collision>
      <origin rpy="0 0 0" xyz="-0.2693 -0.4482 0.0750"/>
      <geometry>
        <box size="0.08 0.08 0.15"/>
      </geometry>
    </collision>
    <collision>
      <origin rpy="0 0 0" xyz="0.10603 -0.4482 0.0750"/>
      <geometry>
        <box size="0.08 0.08 0.15"/>
      </geometry>
    </collision>
    <collision>
      <origin rpy="0 0 0" xyz="-0.2693 0.4482 0.0750"/>
      <geometry>
        <box size="0.08 0.08 0.15"/>
      </geometry>
    </collision>
    <collision>
      <origin rpy="0 0 0" xyz="0.10603 0.4482 0.0750"/>
      <geometry>
        <box size="0.08 0.08 0.15"/>
      </geometry>
    </collision>
    <collision>
      <origin rpy="0 0 0" xyz="-0.0805 0.0000 0.16345"/>
      <geometry>
        <box size="0.487 1.0000 0.0269"/>
      </geometry>
    </collision>
    <collision>
      <origin rpy="0 0 0" xyz="-0.0805 0.48965 0.975"/>
      <geometry>
        <box size="0.487 0.0207 1.65"/>
      </geometry>
    </collision>
    <collision>
      <origin rpy="0 0 0" xyz="-0.0896 0.0000 0.975"/>
      <geometry>
        <box size="0.4318 0.018568 1.65"/>
      </geometry>
    </collision>
    <collision>
      <origin rpy="0 0 0" xyz="-0.0805 -0.48965 0.975"/>
      <geometry>
        <box size="0.487 0.0207 1.65"/>
      </geometry>
    </collision>
    <collision>
      <origin rpy="0 0 0" xyz="0.14465 0.0000 0.975"/>
      <geometry>
        <box size="0.0367 1.0000 1.65"/>
      </geometry>
    </collision>
    <collision>
      <origin rpy="0 0 0" xyz="0.14465 0.0000 0.975"/>
      <geometry>
        <box size="0.0367 1.0000 1.65"/>
      </geometry>
    </collision>
    <collision>
      <origin rpy="0 0 0" xyz="-0.0805 0.0000 1.7865"/>
      <geometry>
        <box size="0.487 1.0000 0.027"/>
      </geometry>
    </collision>
    <collision>
      <origin rpy="0 0 0" xyz="-0.08861 -0.244343 0.5727"/>
      <geometry>
        <box size="0.4299 0.469957 0.0118"/>
      </geometry>
    </collision>
    <collision>
      <origin rpy="0 0 0" xyz="-0.08861 -0.244343 0.974836"/>
      <geometry>
        <box size="0.4299 0.469957 0.0118"/>
      </geometry>
    </collision>
    <collision>
      <origin rpy="0 0 0" xyz="-0.08861 -0.244343 1.37686"/>
      <geometry>
        <box size="0.4299 0.469957 0.0118"/>
      </geometry>
    </collision>
    <collision>
      <origin rpy="1.5708 0 0" xyz="-0.086923 0.244373 1.66898"/>
      <geometry>
        <cylinder length="0.469897" radius="0.0075"/>
      </geometry>
    </collision>
  </link>
  <joint name="wardrobe_door_left_joint" type="revolute">
    <origin rpy="0 0 0" xyz="-0.3246 0.5 0.0000"/>
    <parent link="wardrobe"/>
    <child link="wardrobe_door_left"/>
    <axis xyz="0 0 -1"/>
    <limit effort="1000.0" lower="0.0" upper="1.5708" velocity="1.5708"/>
  </joint>
  <link name="wardrobe_door_left">
    <visual>
      <geometry>
        <mesh filename="package://iai_apartment/meshes/visual/wardrobe_door_left.dae"/>
      </geometry>
    </visual>
    <collision>
      <origin rpy="0 0 0" xyz="-0.006435 -0.2485 0.975"/>
      <geometry>
        <box size="0.012967 0.495438 1.64844"/>
      </geometry>
    </collision>
  </link>
  <joint name="wardrobe_door_left_handle_joint" type="fixed">
    <origin rpy="0 0 0" xyz="-0.032089 -0.460513 0.973703"/>
    <parent link="wardrobe_door_left"/>
    <child link="wardrobe_door_left_handle"/>
  </joint>
  <link name="wardrobe_door_left_handle">
    <visual>
      <geometry>
        <mesh filename="package://iai_apartment/meshes/visual/wardrobe_door_handle.dae"/>
      </geometry>
    </visual>
    <collision>
      <origin rpy="0 0 0" xyz="0.010421 0 0.059003"/>
      <geometry>
        <box size="0.033556 0.015082 0.014587"/>
      </geometry>
    </collision>
    <collision>
      <origin rpy="0 0 0" xyz="-0.0136 0 0"/>
      <geometry>
        <box size="0.014486 0.015082 0.13"/>
      </geometry>
    </collision>
    <collision>
      <origin rpy="0 0 0" xyz="0.010421 0 -0.059003"/>
      <geometry>
        <box size="0.033556 0.015082 0.014587"/>
      </geometry>
    </collision>
  </link>
  <joint name="wardrobe_door_right_joint" type="revolute">
    <origin rpy="0 0 0" xyz="-0.3246 -0.5 0.0000"/>
    <parent link="wardrobe"/>
    <child link="wardrobe_door_right"/>
    <axis xyz="0 0 1"/>
    <limit effort="1000.0" lower="0.0" upper="1.5708" velocity="1.5708"/>
  </joint>
  <link name="wardrobe_door_right">
    <visual>
      <geometry>
        <mesh filename="package://iai_apartment/meshes/visual/wardrobe_door_right.dae"/>
      </geometry>
    </visual>
    <collision>
      <origin rpy="0 0 0" xyz="-0.006435 0.2485 0.975"/>
      <geometry>
        <box size="0.012967 0.495438 1.64844"/>
      </geometry>
    </collision>
  </link>
  <joint name="wardrobe_door_right_handle_joint" type="fixed">
    <origin rpy="0 0 0" xyz="-0.032089 0.460513 0.973703"/>
    <parent link="wardrobe_door_right"/>
    <child link="wardrobe_door_right_handle"/>
  </joint>
  <link name="wardrobe_door_right_handle">
    <visual>
      <geometry>
        <mesh filename="package://iai_apartment/meshes/visual/wardrobe_door_handle.dae"/>
      </geometry>
    </visual>
    <collision>
      <origin rpy="0 0 0" xyz="0.010421 0 0.059003"/>
      <geometry>
        <box size="0.033556 0.015082 0.014587"/>
      </geometry>
    </collision>
    <collision>
      <origin rpy="0 0 0" xyz="-0.0136 0 0"/>
      <geometry>
        <box size="0.014486 0.015082 0.13"/>
      </geometry>
    </collision>
    <collision>
      <origin rpy="0 0 0" xyz="0.010421 0 -0.059003"/>
      <geometry>
        <box size="0.033556 0.015082 0.014587"/>
      </geometry>
    </collision>
  </link>
  <joint name="armchair_joint" type="fixed">
    <origin rpy="0 0 1.9199" xyz="7.9688 -0.3791 0.0"/>
    <parent link="furnitures_root"/>
    <child link="armchair"/>
  </joint>
  <link name="armchair">
    <visual>
      <geometry>
        <mesh filename="package://iai_apartment/meshes/visual/armchair.dae"/>
      </geometry>
    </visual>
    <collision>
      <geometry>
        <mesh filename="package://iai_apartment/meshes/collision/armchair.obj"/>
      </geometry>
    </collision>
  </link>
  <joint name="sofa_joint" type="fixed">
    <origin rpy="0 0 0" xyz="8.1986 2.4096 0.0"/>
    <parent link="furnitures_root"/>
    <child link="sofa"/>
  </joint>
  <link name="sofa">
    <visual>
      <geometry>
        <mesh filename="package://iai_apartment/meshes/visual/sofa.dae"/>
      </geometry>
    </visual>
    <collision>
      <geometry>
        <mesh filename="package://iai_apartment/meshes/collision/sofa.obj"/>
      </geometry>
    </collision>
  </link>
  <joint name="coffee_table_joint" type="fixed">
    <origin rpy="0 0 1.5708" xyz="7.8034 1.02957 0.0"/>
    <parent link="furnitures_root"/>
    <child link="coffee_table"/>
  </joint>
  <link name="coffee_table">
    <visual>
      <geometry>
        <mesh filename="package://iai_apartment/meshes/visual/coffee_table.dae"/>
      </geometry>
    </visual>
    <collision>
      <origin rpy="0 0 0" xyz="0.0000 0.0000 0.02977"/>
      <geometry>
        <box size="0.58 1.08 0.05954"/>
      </geometry>
    </collision>
    <collision>
      <origin rpy="0 0 0" xyz="-0.022101 0.0000 0.06552"/>
      <geometry>
        <box size="0.6106 0.4 0.01196"/>
      </geometry>
    </collision>
    <collision>
      <origin rpy="0 0 0" xyz="0.0000 0.39975 0.220625"/>
      <geometry>
        <box size="0.7 0.4 0.32"/>
      </geometry>
    </collision>
    <collision>
      <origin rpy="0 0 0" xyz="0.0000 -0.39975 0.220625"/>
      <geometry>
        <box size="0.7 0.4 0.32"/>
      </geometry>
    </collision>
    <collision>
      <origin rpy="0 0 0" xyz="0.316343 0.0000 0.22"/>
      <geometry>
        <box size="0.0673 0.4 0.32"/>
      </geometry>
    </collision>
    <collision>
      <origin rpy="0 0 0" xyz="0.0000 0.0000 0.39"/>
      <geometry>
        <box size="0.7 1.2 0.02"/>
      </geometry>
    </collision>
  </link>
  <joint name="coffee_table_drawer_joint" type="prismatic">
    <parent link="coffee_table"/>
    <child link="coffee_table_drawer"/>
    <axis xyz="-1 0 0"/>
    <limit effort="1000.0" lower="0.0" upper="0.5" velocity="0.5"/>
  </joint>
  <link name="coffee_table_drawer">
    <visual>
      <geometry>
        <mesh filename="package://iai_apartment/meshes/visual/coffee_table_drawer.dae"/>
      </geometry>
    </visual>
    <collision>
      <origin rpy="0 0 0" xyz="-0.338806 0.0000 0.21892"/>
      <geometry>
        <box size="0.0214 0.396 0.31569"/>
      </geometry>
    </collision>
    <collision>
      <origin rpy="0 0 0" xyz="-0.051066 0.0000 0.107979"/>
      <geometry>
        <box size="0.5521 0.3454 0.02144"/>
      </geometry>
    </collision>
    <collision>
      <origin rpy="0 0 0" xyz="0.207974 0.0000 0.238907"/>
      <geometry>
        <box size="0.0214 0.3486 0.2398"/>
      </geometry>
    </collision>
    <collision>
      <origin rpy="0 0 0" xyz="-0.051066 -0.186206 0.226597"/>
      <geometry>
        <box size="0.5521 0.0214 0.26425"/>
      </geometry>
    </collision>
    <collision>
      <origin rpy="0 0 0" xyz="-0.051066 0.186206 0.226597"/>
      <geometry>
        <box size="0.5521 0.0214 0.26425"/>
      </geometry>
    </collision>
  </link>
  <joint name="bedside_table_joint" type="fixed">
    <origin rpy="0 0 0" xyz="7.2110 0.1296 0.0"/>
    <parent link="furnitures_root"/>
    <child link="bedside_table"/>
  </joint>
  <link name="bedside_table">
    <visual>
      <geometry>
        <mesh filename="package://iai_apartment/meshes/visual/bedside_table.dae"/>
      </geometry>
    </visual>
    <collision>
      <origin rpy="0 0 0" xyz="0.0000 0.0000 0.230"/>
      <geometry>
        <box size="0.312 0.312 0.460"/>
      </geometry>
    </collision>
  </link>
  <joint name="kitchen_base" type="fixed">
    <origin xyz="0.0 0.0 0.0"/>
    <parent link="apartment_root"/>
    <child link="kitchen_root"/>
  </joint>
  <link name="kitchen_root"/>
  <!-- First part of the kitchen (fridge) -->
  <joint name="kitchen1_root_joint" type="fixed">
    <origin xyz="0.0 0.0 0.0"/>
    <parent link="kitchen_root"/>
    <child link="kitchen1_root"/>
  </joint>
  <link name="kitchen1_root"/>
  <!-- Cabinet1 -->
  <joint name="cabinet1_joint" type="fixed">
    <origin rpy="0.0 0.0 1.5707963267948966" xyz="0.28463219 1.46675873 1.11440605"/>
    <parent link="kitchen1_root"/>
    <child link="cabinet1"/>
  </joint>
  <link name="cabinet1">
    <visual>
      <geometry>
        <mesh filename="package://iai_apartment/meshes/unreal/SM_Kitchen_01_Base.dae"/>
      </geometry>
    </visual>
    <collision>
      <origin xyz="0.3 0.010499 0.05"/>
      <geometry>
        <box size="0.019 0.55494 2.12778"/>
      </geometry>
    </collision>
    <collision>
      <origin xyz="-0.280469 0.010499 0.05"/>
      <geometry>
        <box size="0.019 0.55494 2.12778"/>
      </geometry>
    </collision>
    <collision>
      <origin xyz="0.009901 0.271973 0.041995"/>
      <geometry>
        <box size="0.561938 0.008 2.11178"/>
      </geometry>
    </collision>
    <collision>
      <origin xyz="-0.299967 0.0 0.0"/>
      <geometry>
        <box size="0.02092 0.575938 2.22776"/>
      </geometry>
    </collision>
    <collision>
      <origin xyz="0.009901 -0.254976 1.06578"/>
      <geometry>
        <box size="0.561938 0.016 0.064"/>
      </geometry>
    </collision>
    <collision>
      <origin xyz="0.009901 0.0055 1.10578"/>
      <geometry>
        <box size="0.561938 0.540942 0.016"/>
      </geometry>
    </collision>
    <collision>
      <origin xyz="0.009901 0.0005 0.249501"/>
      <geometry>
        <box size="0.561938 0.540942 0.015"/>
      </geometry>
    </collision>
    <collision>
      <origin xyz="0.009901 0.0005 -0.361161 "/>
      <geometry>
        <box size="0.561938 0.534942 0.015"/>
      </geometry>
    </collision>
  </link>
  <joint name="cabinet1_door_joint" type="revolute">
    <origin rpy="0.0 0.0 0.0" xyz="-0.280 -0.280 0.677"/>
    <parent link="cabinet1"/>
    <child link="cabinet1_door"/>
    <axis xyz="0 0 -1"/>
    <limit effort="1000.0" lower="0.0" upper="1.5707963267948966" velocity="1.5707963267948966"/>
  </joint>
  <link name="cabinet1_door">
    <visual>
      <geometry>
        <mesh filename="package://iai_apartment/meshes/unreal/SM_Kitchen_01_Door_01.dae"/>
      </geometry>
    </visual>
    <collision>
      <origin xyz="0.285091 0.0 0.0"/>
      <geometry>
        <box size="0.596936 0.019 0.86681"/>
      </geometry>
    </collision>
  </link>
  <joint name="cabinet1_door_handle_joint" type="fixed">
    <origin rpy="0.0 0.0 1.5707963267948966" xyz="0.46315559 -0.01559982 -0.38983368"/>
    <parent link="cabinet1_door"/>
    <child link="cabinet1_door_handle"/>
  </joint>
  <link name="cabinet1_door_handle">
    <visual>
      <geometry>
        <mesh filename="package://iai_apartment/meshes/unreal/SM_Kitchen_Handle.dae"/>
      </geometry>
    </visual>
    <collision>
      <origin xyz="-0.003891 0.08 0.0"/>
      <geometry>
        <box size="0.02 0.013 0.013"/>
      </geometry>
    </collision>
    <collision>
      <origin xyz="-0.003891 -0.08 0.0"/>
      <geometry>
        <box size="0.02 0.013 0.013"/>
      </geometry>
    </collision>
    <collision>
      <origin xyz="-0.0203895 0.0 0.0"/>
      <geometry>
        <box size="0.013 0.173032  0.013"/>
      </geometry>
    </collision>
  </link>
  <joint name="cabinet1_drawer1_joint" type="prismatic">
    <origin rpy="0.0 0.0 0.0" xyz="0.01122015 -0.04679018 -0.48658508"/>
    <parent link="cabinet1"/>
    <child link="cabinet1_drawer1"/>
    <axis xyz="0 -1 0"/>
    <limit effort="1000.0" lower="0.0" upper="0.45" velocity="0.5"/>
  </joint>
  <link name="cabinet1_drawer1">
    <visual>
      <geometry>
        <mesh filename="package://iai_apartment/meshes/unreal/SM_Kitchen_01_Drawer_01.dae"/>
      </geometry>
    </visual>
    <collision>
      <origin xyz="0.0 -0.233977 0.0"/>
      <geometry>
        <box size="0.596936 0.019 0.262972"/>
      </geometry>
    </collision>
    <collision>
      <origin xyz="0.26865 0.021336 0.0412455"/>
      <geometry>
        <box size="0.0158442 0.4917 0.0223924"/>
      </geometry>
    </collision>
    <collision>
      <origin xyz="-0.26865 0.021336 0.0412455"/>
      <geometry>
        <box size="0.0158442 0.4917 0.0223924"/>
      </geometry>
    </collision>
    <collision>
      <origin xyz="0.26865 0.021336 -0.078968"/>
      <geometry>
        <box size="0.0158442 0.4917 0.083496"/>
      </geometry>
    </collision>
    <collision>
      <origin xyz="-0.26865 0.021336 -0.0941"/>
      <geometry>
        <box size="0.0158442 0.4917 0.053098"/>
      </geometry>
    </collision>
    <collision>
      <origin xyz="0.0 0.021399 -0.114232"/>
      <geometry>
        <box size="0.52364 0.49156 0.016"/>
      </geometry>
    </collision>
    <collision>
      <origin xyz="0.0 0.26 -0.038"/>
      <geometry>
        <box size="0.52364 0.01865384 0.16887"/>
      </geometry>
    </collision>
  </link>
  <joint name="cabinet1_drawer1_handle_joint" type="fixed">
    <origin rpy="0.0 0.0 1.5707963267948966" xyz="0.00091816 -0.24792936 0.08401428"/>
    <parent link="cabinet1_drawer1"/>
    <child link="cabinet1_drawer1_handle"/>
  </joint>
  <link name="cabinet1_drawer1_handle">
    <visual>
      <geometry>
        <mesh filename="package://iai_apartment/meshes/unreal/SM_Kitchen_Handle.dae"/>
      </geometry>
    </visual>
    <collision>
      <origin xyz="-0.003891 0.08 0.0"/>
      <geometry>
        <box size="0.02 0.013 0.013"/>
      </geometry>
    </collision>
    <collision>
      <origin xyz="-0.003891 -0.08 0.0"/>
      <geometry>
        <box size="0.02 0.013 0.013"/>
      </geometry>
    </collision>
    <collision>
      <origin xyz="-0.0203895 0.0 0.0"/>
      <geometry>
        <box size="0.013 0.173032  0.013"/>
      </geometry>
    </collision>
  </link>
  <joint name="cabinet1_drawer2_joint" type="prismatic">
    <origin rpy="0.0 0.0 0.0" xyz="0.011 -0.046 -0.816"/>
    <parent link="cabinet1"/>
    <child link="cabinet1_drawer2"/>
    <axis xyz="0 -1 0"/>
    <limit effort="1000.0" lower="0.0" upper="0.45" velocity="0.5"/>
  </joint>
  <link name="cabinet1_drawer2">
    <visual>
      <geometry>
        <mesh filename="package://iai_apartment/meshes/unreal/SM_Kitchen_01_Drawer_02.dae"/>
      </geometry>
    </visual>
    <collision>
      <origin xyz="0.0 -0.233977 0.0"/>
      <geometry>
        <box size="0.596936 0.019 0.39428"/>
      </geometry>
    </collision>
    <collision>
      <origin xyz="0.26865 0.021336 -0.0084109"/>
      <geometry>
        <box size="0.0158442 0.4917 0.0223924"/>
      </geometry>
    </collision>
    <collision>
      <origin xyz="-0.26865 0.021336 -0.0084109"/>
      <geometry>
        <box size="0.0158442 0.4917 0.0223924"/>
      </geometry>
    </collision>
    <collision>
      <origin xyz="0.26865 0.021336 -0.12854"/>
      <geometry>
        <box size="0.0158442 0.4917 0.083502"/>
      </geometry>
    </collision>
    <collision>
      <origin xyz="-0.26865 0.021336 -0.12854"/>
      <geometry>
        <box size="0.0158442 0.4917 0.083502"/>
      </geometry>
    </collision>
    <collision>
      <origin xyz="0.0 0.021399 -0.16226"/>
      <geometry>
        <box size="0.52364 0.49156 0.016"/>
      </geometry>
    </collision>
    <collision>
      <origin xyz="0.0 0.26 -0.0797358 "/>
      <geometry>
        <box size="0.52364 0.01865384 0.1517224"/>
      </geometry>
    </collision>
  </link>
  <joint name="cabinet1_drawer2_handle_joint" type="fixed">
    <origin rpy="0.0 0.0 1.5707963267948966" xyz="0.00145845 -0.24909416 0.150606"/>
    <parent link="cabinet1_drawer2"/>
    <child link="cabinet1_drawer2_handle"/>
  </joint>
  <link name="cabinet1_drawer2_handle">
    <visual>
      <geometry>
        <mesh filename="package://iai_apartment/meshes/unreal/SM_Kitchen_Handle.dae"/>
      </geometry>
    </visual>
    <collision>
      <origin xyz="-0.003891 0.08 0.0"/>
      <geometry>
        <box size="0.02 0.013 0.013"/>
      </geometry>
    </collision>
    <collision>
      <origin xyz="-0.003891 -0.08 0.0"/>
      <geometry>
        <box size="0.02 0.013 0.013"/>
      </geometry>
    </collision>
    <collision>
      <origin xyz="-0.0203895 0.0 0.0"/>
      <geometry>
        <box size="0.013 0.173032  0.013"/>
      </geometry>
    </collision>
  </link>
  <joint name="oven_joint" type="fixed">
    <origin rpy="0 0 0" xyz="0.0123597 -0.27395857 -0.3426725"/>
    <parent link="cabinet1"/>
    <child link="oven"/>
  </joint>
  <link name="oven">
    <visual>
      <geometry>
        <mesh filename="package://iai_apartment/meshes/unreal/SM_Oven.dae"/>
      </geometry>
    </visual>
    <collision>
      <origin xyz="-0.003055 0.264778 0.50654"/>
      <geometry>
        <box size="0.58989 0.545666 0.150842"/>
      </geometry>
    </collision>
    <collision>
      <origin xyz="-0.003055 0.264778 0.018039"/>
      <geometry>
        <box size="0.58989 0.545666 0.045598"/>
      </geometry>
    </collision>
    <collision>
      <origin xyz="-0.2675 0.264778 0.288951"/>
      <geometry>
        <box size="0.059 0.545666 0.586022"/>
      </geometry>
    </collision>
    <collision>
      <origin xyz="0.264104 0.264778 0.288951"/>
      <geometry>
        <box size="0.054902 0.545666 0.586022"/>
      </geometry>
    </collision>
    <collision>
      <origin xyz="-0.003055 0.5 0.288951"/>
      <geometry>
        <box size="0.58989 0.074784 0.586022"/>
      </geometry>
    </collision>
  </link>
  <joint name="oven_door_joint" type="revolute">
    <origin rpy="0 0 0" xyz="0.0 0.0 0.0"/>
    <parent link="oven"/>
    <child link="oven_door"/>
    <axis xyz="1 0 0"/>
    <limit effort="1000.0" lower="0.0" upper="1.5707963267948966" velocity="1.5707963267948966"/>
  </joint>
  <link name="oven_door">
    <visual>
      <geometry>
        <mesh filename="package://iai_apartment/meshes/unreal/SM_Oven_Door.dae"/>
      </geometry>
    </visual>
    <collision>
      <origin xyz="-0.002993 0.005395 0.226757"/>
      <geometry>
        <box size="0.590588 0.036998 0.471696"/>
      </geometry>
    </collision>
  </link>
  <!-- Cabinet2 -->
  <joint name="cabinet2_joint" type="fixed">
    <origin rpy="0.0 0.0 1.5707963267948966" xyz="0.27990936 1.97705429 1.16238914"/>
    <parent link="kitchen1_root"/>
    <child link="cabinet2"/>
  </joint>
  <link name="cabinet2">
    <visual>
      <geometry>
        <mesh filename="package://iai_apartment/meshes/unreal/SM_Kitchen_02_Base.dae"/>
      </geometry>
    </visual>
    <collision>
      <origin xyz="-0.191979 0.005897 0.0"/>
      <geometry>
        <box size="0.016 0.554718 2.12768"/>
      </geometry>
    </collision>
    <collision>
      <origin xyz="0.191979 0.005897 0.0"/>
      <geometry>
        <box size="0.016 0.554718 2.12768"/>
      </geometry>
    </collision>
    <collision>
      <origin xyz="0.0 0.005897 1.05584"/>
      <geometry>
        <box size="0.367764 0.554718 0.016"/>
      </geometry>
    </collision>
    <collision>
      <origin xyz="0.0 0.005897 0.975845"/>
      <geometry>
        <box size="0.367764 0.554718 0.016"/>
      </geometry>
    </collision>
    <collision>
      <origin xyz="0.0 0.005897 -1.05594"/>
      <geometry>
        <box size="0.367764 0.554718 0.016"/>
      </geometry>
    </collision>
    <collision>
      <origin xyz="0.0 -0.26039 1.01584"/>
      <geometry>
        <box size="0.367764 0.014374 0.063992"/>
      </geometry>
    </collision>
    <collision>
      <origin xyz="0.0 0.267372 0.0"/>
      <geometry>
        <box size="0.367764 0.008 2.09568"/>
      </geometry>
    </collision>
  </link>
  <joint name="cabinet2_door_joint" type="revolute">
    <origin rpy="0.0 0.0 0.0" xyz="-0.18657 -0.28432144 0.00105865"/>
    <parent link="cabinet2"/>
    <child link="cabinet2_door"/>
    <axis xyz="0 0 -1"/>
    <limit effort="1000.0" lower="0.0" upper="1.5707963267948966" velocity="1.5707963267948966"/>
  </joint>
  <link name="cabinet2_door">
    <visual>
      <geometry>
        <mesh filename="package://iai_apartment/meshes/unreal/SM_Kitchen_02_Door.dae"/>
      </geometry>
    </visual>
    <collision>
      <origin xyz="0.185074 -0.000653 0.0"/>
      <geometry>
        <box size="0.396958 0.019 2.12276"/>
      </geometry>
    </collision>
  </link>
  <joint name="cabinet2_door_handle_joint" type="fixed">
    <origin rpy="0.0 0.0 1.5707963267948966" xyz="0.25886013 -0.00184994 -0.05118866"/>
    <parent link="cabinet2_door"/>
    <child link="cabinet2_door_handle"/>
  </joint>
  <link name="cabinet2_door_handle">
    <visual>
      <geometry>
        <mesh filename="package://iai_apartment/meshes/unreal/SM_Kitchen_Handle.dae"/>
      </geometry>
    </visual>
    <collision>
      <origin xyz="-0.003891 0.08 0.0"/>
      <geometry>
        <box size="0.02 0.013 0.013"/>
      </geometry>
    </collision>
    <collision>
      <origin xyz="-0.003891 -0.08 0.0"/>
      <geometry>
        <box size="0.02 0.013 0.013"/>
      </geometry>
    </collision>
    <collision>
      <origin xyz="-0.0203895 0.0 0.0"/>
      <geometry>
        <box size="0.013 0.173032  0.013"/>
      </geometry>
    </collision>
  </link>
  <joint name="cabinet2_shelf_joint" type="fixed">
    <origin rpy="0.0 0.0 0.0" xyz="-0.00043732 -0.00337784 0.79036064"/>
    <parent link="cabinet2"/>
    <child link="cabinet2_shelf"/>
  </joint>
  <link name="cabinet2_shelf">
    <visual>
      <geometry>
        <mesh filename="package://iai_apartment/meshes/unreal/SM_Kitchen_02_Shelf.dae"/>
      </geometry>
    </visual>
  </link>
  <joint name="cabinet2_drawer1_joint" type="prismatic">
    <origin rpy="0.0 0.0 0.0" xyz="0.00134538 -0.00464775 0.58046211"/>
    <parent link="cabinet2"/>
    <child link="cabinet2_drawer1"/>
    <axis xyz="0 -1 0"/>
    <limit effort="1000.0" lower="0.0" upper="0.45" velocity="0.5"/>
  </joint>
  <link name="cabinet2_drawer1">
    <visual>
      <geometry>
        <mesh filename="package://iai_apartment/meshes/unreal/SM_Kitchen_02_Drawer_01.dae"/>
      </geometry>
    </visual>
    <collision>
      <origin xyz="0.0 -0.242975 0.0"/>
      <geometry>
        <box size="0.361962 0.017 0.10099"/>
      </geometry>
    </collision>
    <collision>
      <origin xyz="0.0 0.235441 0.0"/>
      <geometry>
        <box size="0.361962 0.016128 0.10099"/>
      </geometry>
    </collision>
    <collision>
      <origin xyz="-0.170578 -0.003984 0.0"/>
      <geometry>
        <box size="0.016 0.494978 0.10099"/>
      </geometry>
    </collision>
    <collision>
      <origin xyz="0.170578 -0.003984 0.0"/>
      <geometry>
        <box size="0.016 0.494978 0.10099"/>
      </geometry>
    </collision>
    <collision>
      <origin xyz="0.0 -0.003984 -0.039746"/>
      <geometry>
        <box size="0.361962 0.494978 0.021498"/>
      </geometry>
    </collision>
  </link>
  <joint name="cabinet2_drawer2_joint" type="prismatic">
    <origin rpy="0.0 0.0 0.0" xyz="0.00134538 -0.00464775 0.4227494"/>
    <parent link="cabinet2"/>
    <child link="cabinet2_drawer2"/>
    <axis xyz="0 -1 0"/>
    <limit effort="1000.0" lower="0.0" upper="0.45" velocity="0.5"/>
  </joint>
  <link name="cabinet2_drawer2">
    <visual>
      <geometry>
        <mesh filename="package://iai_apartment/meshes/unreal/SM_Kitchen_02_Drawer_02.dae"/>
      </geometry>
    </visual>
    <collision>
      <origin xyz="0.0 -0.242374 -0.042"/>
      <geometry>
        <box size="0.361962 0.013796 0.098"/>
      </geometry>
    </collision>
    <collision>
      <origin xyz="0.0 -0.242374 0.060843"/>
      <geometry>
        <box size="0.361962 0.013796 0.020298"/>
      </geometry>
    </collision>
    <collision>
      <origin xyz="-0.148428 -0.242869 0.0"/>
      <geometry>
        <box size="0.064882 0.016786 0.18198"/>
      </geometry>
    </collision>
    <collision>
      <origin xyz="0.148428 -0.242869 0.0"/>
      <geometry>
        <box size="0.064882 0.016786 0.18198"/>
      </geometry>
    </collision>
    <collision>
      <origin xyz="0.0 0.235441 0.0"/>
      <geometry>
        <box size="0.361962 0.016128 0.181758"/>
      </geometry>
    </collision>
    <collision>
      <origin xyz="-0.170578 -0.003984 0.075342"/>
      <geometry>
        <box size="0.016 0.494978 0.023298"/>
      </geometry>
    </collision>
    <collision>
      <origin xyz="0.170578 -0.003984 0.075342"/>
      <geometry>
        <box size="0.016 0.494978 0.023298"/>
      </geometry>
    </collision>
    <collision>
      <origin xyz="-0.170578 -0.003984 -0.043743"/>
      <geometry>
        <box size="0.016 0.494978 0.087106"/>
      </geometry>
    </collision>
    <collision>
      <origin xyz="0.170578 -0.003984 -0.043743"/>
      <geometry>
        <box size="0.016 0.494978 0.087106"/>
      </geometry>
    </collision>
    <collision>
      <origin xyz="0.0 -0.003984 -0.080242"/>
      <geometry>
        <box size="0.361962 0.494978 0.021498"/>
      </geometry>
    </collision>
  </link>
  <joint name="cabinet2_drawer3_joint" type="prismatic">
    <origin rpy="0.0 0.0 0.0" xyz="0.00134538 -0.00464775 0.1428965"/>
    <parent link="cabinet2"/>
    <child link="cabinet2_drawer3"/>
    <axis xyz="0 -1 0"/>
    <limit effort="1000.0" lower="0.0" upper="0.45" velocity="0.5"/>
  </joint>
  <link name="cabinet2_drawer3">
    <visual>
      <geometry>
        <mesh filename="package://iai_apartment/meshes/unreal/SM_Kitchen_02_Drawer_02.dae"/>
      </geometry>
    </visual>
    <collision>
      <origin xyz="0.0 -0.242374 -0.042"/>
      <geometry>
        <box size="0.361962 0.013796 0.098"/>
      </geometry>
    </collision>
    <collision>
      <origin xyz="0.0 -0.242374 0.060843"/>
      <geometry>
        <box size="0.361962 0.013796 0.020298"/>
      </geometry>
    </collision>
    <collision>
      <origin xyz="-0.148428 -0.242869 0.0"/>
      <geometry>
        <box size="0.064882 0.016786 0.18198"/>
      </geometry>
    </collision>
    <collision>
      <origin xyz="0.148428 -0.242869 0.0"/>
      <geometry>
        <box size="0.064882 0.016786 0.18198"/>
      </geometry>
    </collision>
    <collision>
      <origin xyz="0.0 0.235441 0.0"/>
      <geometry>
        <box size="0.361962 0.016128 0.181758"/>
      </geometry>
    </collision>
    <collision>
      <origin xyz="-0.170578 -0.003984 0.075342"/>
      <geometry>
        <box size="0.016 0.494978 0.023298"/>
      </geometry>
    </collision>
    <collision>
      <origin xyz="0.170578 -0.003984 0.075342"/>
      <geometry>
        <box size="0.016 0.494978 0.023298"/>
      </geometry>
    </collision>
    <collision>
      <origin xyz="-0.170578 -0.003984 -0.043743"/>
      <geometry>
        <box size="0.016 0.494978 0.087106"/>
      </geometry>
    </collision>
    <collision>
      <origin xyz="0.170578 -0.003984 -0.043743"/>
      <geometry>
        <box size="0.016 0.494978 0.087106"/>
      </geometry>
    </collision>
    <collision>
      <origin xyz="0.0 -0.003984 -0.080242"/>
      <geometry>
        <box size="0.361962 0.494978 0.021498"/>
      </geometry>
    </collision>
  </link>
  <joint name="cabinet2_drawer4_joint" type="prismatic">
    <origin rpy="0.0 0.0 0.0" xyz="0.00134538 -0.00464775 -0.24243713"/>
    <parent link="cabinet2"/>
    <child link="cabinet2_drawer4"/>
    <axis xyz="0 -1 0"/>
    <limit effort="1000.0" lower="0.0" upper="0.45" velocity="0.5"/>
  </joint>
  <link name="cabinet2_drawer4">
    <visual>
      <geometry>
        <mesh filename="package://iai_apartment/meshes/unreal/SM_Kitchen_02_Drawer_02.dae"/>
      </geometry>
    </visual>
    <collision>
      <origin xyz="0.0 -0.242374 -0.042"/>
      <geometry>
        <box size="0.361962 0.013796 0.098"/>
      </geometry>
    </collision>
    <collision>
      <origin xyz="0.0 -0.242374 0.060843"/>
      <geometry>
        <box size="0.361962 0.013796 0.020298"/>
      </geometry>
    </collision>
    <collision>
      <origin xyz="-0.148428 -0.242869 0.0"/>
      <geometry>
        <box size="0.064882 0.016786 0.18198"/>
      </geometry>
    </collision>
    <collision>
      <origin xyz="0.148428 -0.242869 0.0"/>
      <geometry>
        <box size="0.064882 0.016786 0.18198"/>
      </geometry>
    </collision>
    <collision>
      <origin xyz="0.0 0.235441 0.0"/>
      <geometry>
        <box size="0.361962 0.016128 0.181758"/>
      </geometry>
    </collision>
    <collision>
      <origin xyz="-0.170578 -0.003984 0.075342"/>
      <geometry>
        <box size="0.016 0.494978 0.023298"/>
      </geometry>
    </collision>
    <collision>
      <origin xyz="0.170578 -0.003984 0.075342"/>
      <geometry>
        <box size="0.016 0.494978 0.023298"/>
      </geometry>
    </collision>
    <collision>
      <origin xyz="-0.170578 -0.003984 -0.043743"/>
      <geometry>
        <box size="0.016 0.494978 0.087106"/>
      </geometry>
    </collision>
    <collision>
      <origin xyz="0.170578 -0.003984 -0.043743"/>
      <geometry>
        <box size="0.016 0.494978 0.087106"/>
      </geometry>
    </collision>
    <collision>
      <origin xyz="0.0 -0.003984 -0.080242"/>
      <geometry>
        <box size="0.361962 0.494978 0.021498"/>
      </geometry>
    </collision>
  </link>
  <joint name="cabinet2_drawer5_joint" type="prismatic">
    <origin rpy="0.0 0.0 0.0" xyz="0.00134538 -0.00464775 -0.51809593"/>
    <parent link="cabinet2"/>
    <child link="cabinet2_drawer5"/>
    <axis xyz="0 -1 0"/>
    <limit effort="1000.0" lower="0.0" upper="0.45" velocity="0.5"/>
  </joint>
  <link name="cabinet2_drawer5">
    <visual>
      <geometry>
        <mesh filename="package://iai_apartment/meshes/unreal/SM_Kitchen_02_Drawer_02.dae"/>
      </geometry>
    </visual>
    <collision>
      <origin xyz="0.0 -0.242374 -0.042"/>
      <geometry>
        <box size="0.361962 0.013796 0.098"/>
      </geometry>
    </collision>
    <collision>
      <origin xyz="0.0 -0.242374 0.060843"/>
      <geometry>
        <box size="0.361962 0.013796 0.020298"/>
      </geometry>
    </collision>
    <collision>
      <origin xyz="-0.148428 -0.242869 0.0"/>
      <geometry>
        <box size="0.064882 0.016786 0.18198"/>
      </geometry>
    </collision>
    <collision>
      <origin xyz="0.148428 -0.242869 0.0"/>
      <geometry>
        <box size="0.064882 0.016786 0.18198"/>
      </geometry>
    </collision>
    <collision>
      <origin xyz="0.0 0.235441 0.0"/>
      <geometry>
        <box size="0.361962 0.016128 0.181758"/>
      </geometry>
    </collision>
    <collision>
      <origin xyz="-0.170578 -0.003984 0.075342"/>
      <geometry>
        <box size="0.016 0.494978 0.023298"/>
      </geometry>
    </collision>
    <collision>
      <origin xyz="0.170578 -0.003984 0.075342"/>
      <geometry>
        <box size="0.016 0.494978 0.023298"/>
      </geometry>
    </collision>
    <collision>
      <origin xyz="-0.170578 -0.003984 -0.043743"/>
      <geometry>
        <box size="0.016 0.494978 0.087106"/>
      </geometry>
    </collision>
    <collision>
      <origin xyz="0.170578 -0.003984 -0.043743"/>
      <geometry>
        <box size="0.016 0.494978 0.087106"/>
      </geometry>
    </collision>
    <collision>
      <origin xyz="0.0 -0.003984 -0.080242"/>
      <geometry>
        <box size="0.361962 0.494978 0.021498"/>
      </geometry>
    </collision>
  </link>
  <joint name="cabinet2_drawer6_joint" type="prismatic">
    <origin rpy="0.0 0.0 0.0" xyz="0.00134538 -0.00464775 -0.95519203"/>
    <parent link="cabinet2"/>
    <child link="cabinet2_drawer6"/>
    <axis xyz="0 -1 0"/>
    <limit effort="1000.0" lower="0.0" upper="0.45" velocity="0.5"/>
  </joint>
  <link name="cabinet2_drawer6">
    <visual>
      <geometry>
        <mesh filename="package://iai_apartment/meshes/unreal/SM_Kitchen_02_Drawer_02.dae"/>
      </geometry>
    </visual>
    <collision>
      <origin xyz="0.0 -0.242374 -0.042"/>
      <geometry>
        <box size="0.361962 0.013796 0.098"/>
      </geometry>
    </collision>
    <collision>
      <origin xyz="0.0 -0.242374 0.060843"/>
      <geometry>
        <box size="0.361962 0.013796 0.020298"/>
      </geometry>
    </collision>
    <collision>
      <origin xyz="-0.148428 -0.242869 0.0"/>
      <geometry>
        <box size="0.064882 0.016786 0.18198"/>
      </geometry>
    </collision>
    <collision>
      <origin xyz="0.148428 -0.242869 0.0"/>
      <geometry>
        <box size="0.064882 0.016786 0.18198"/>
      </geometry>
    </collision>
    <collision>
      <origin xyz="0.0 0.235441 0.0"/>
      <geometry>
        <box size="0.361962 0.016128 0.181758"/>
      </geometry>
    </collision>
    <collision>
      <origin xyz="-0.170578 -0.003984 0.075342"/>
      <geometry>
        <box size="0.016 0.494978 0.023298"/>
      </geometry>
    </collision>
    <collision>
      <origin xyz="0.170578 -0.003984 0.075342"/>
      <geometry>
        <box size="0.016 0.494978 0.023298"/>
      </geometry>
    </collision>
    <collision>
      <origin xyz="-0.170578 -0.003984 -0.043743"/>
      <geometry>
        <box size="0.016 0.494978 0.087106"/>
      </geometry>
    </collision>
    <collision>
      <origin xyz="0.170578 -0.003984 -0.043743"/>
      <geometry>
        <box size="0.016 0.494978 0.087106"/>
      </geometry>
    </collision>
    <collision>
      <origin xyz="0.0 -0.003984 -0.080242"/>
      <geometry>
        <box size="0.361962 0.494978 0.021498"/>
      </geometry>
    </collision>
  </link>
  <!-- Cabinet3 -->
  <joint name="cabinet3_joint" type="fixed">
    <origin rpy="0.0 0.0 1.5707963267948966" xyz="0.27498539 2.47989822 1.16287888"/>
    <parent link="kitchen1_root"/>
    <child link="cabinet3"/>
  </joint>
  <link name="cabinet3">
    <visual>
      <geometry>
        <mesh filename="package://iai_apartment/meshes/unreal/SM_Kitchen_03_Fridge.dae"/>
      </geometry>
    </visual>
    <collision>
      <origin xyz="0.291968 0.003155 0.0"/>
      <geometry>
        <box size="0.02 0.554386 2.12764"/>
      </geometry>
    </collision>
    <collision>
      <origin xyz="-0.291968 0.003155 0.0"/>
      <geometry>
        <box size="0.02 0.554386 2.12764"/>
      </geometry>
    </collision>
    <collision>
      <origin xyz="0.0 0.003155 1.05584"/>
      <geometry>
        <box size="0.572134 0.554386 0.016"/>
      </geometry>
    </collision>
    <collision>
      <origin xyz="0.0 0.003155 0.895854"/>
      <geometry>
        <box size="0.572134 0.554386 0.016"/>
      </geometry>
    </collision>
    <collision>
      <origin xyz="0.0 0.003155 0.819863"/>
      <geometry>
        <box size="0.572134 0.554386 0.016"/>
      </geometry>
    </collision>
    <collision>
      <origin xyz="0.0 0.003155 -0.980943"/>
      <geometry>
        <box size="0.572134 0.554386 0.016"/>
      </geometry>
    </collision>
    <collision>
      <origin xyz="0.0 0.003155 -1.05594"/>
      <geometry>
        <box size="0.572134 0.554386 0.016"/>
      </geometry>
    </collision>
    <collision>
      <origin xyz="0.0 -0.262453 0.975825"/>
      <geometry>
        <box size="0.572134 0.0209188 0.14402"/>
      </geometry>
    </collision>
    <collision>
      <origin xyz="0.0 -0.262453 0.857803"/>
      <geometry>
        <box size="0.572134 0.0209188 0.06"/>
      </geometry>
    </collision>
    <collision>
      <origin xyz="0.0 -0.262453 0.857803"/>
      <geometry>
        <box size="0.572134 0.0209188 0.06"/>
      </geometry>
    </collision>
    <collision>
      <origin xyz="0.20788 -0.264485 -1.02629"/>
      <geometry>
        <box size="0.147984 0.016 0.074692"/>
      </geometry>
    </collision>
  </link>
  <joint name="fridge_door1_joint" type="revolute">
    <origin rpy="0.0 0.0 0.0" xyz="-0.29914526 -0.29725901 0.25673996"/>
    <parent link="cabinet3"/>
    <child link="fridge_door1"/>
    <axis xyz="0 0 -1"/>
    <limit effort="1000.0" lower="0.0" upper="1.5707963267948966" velocity="1.5707963267948966"/>
  </joint>
  <link name="fridge_door1">
    <visual>
      <geometry>
        <mesh filename="package://iai_apartment/meshes/unreal/SM_Fridge_Door_01.dae"/>
      </geometry>
    </visual>
    <collision>
      <origin xyz="0.297325 0.006948 0.139709"/>
      <geometry>
        <box size="0.596492 0.018554 1.336678"/>
      </geometry>
    </collision>
    <collision>
      <origin xyz="0.295455 0.03605 -0.001115"/>
      <geometry>
        <box size="0.553734 0.025 0.988894"/>
      </geometry>
    </collision>
  </link>
  <joint name="fridge_door1_handle_joint" type="fixed">
    <origin rpy="0.0 0.0 1.5707963267948966" xyz="0.46534321 -0.00799103 -0.4736869"/>
    <parent link="fridge_door1"/>
    <child link="fridge_door1_handle"/>
  </joint>
  <link name="fridge_door1_handle">
    <visual>
      <geometry>
        <mesh filename="package://iai_apartment/meshes/unreal/SM_Kitchen_Handle.dae"/>
      </geometry>
    </visual>
    <collision>
      <origin xyz="-0.003891 0.08 0.0"/>
      <geometry>
        <box size="0.02 0.013 0.013"/>
      </geometry>
    </collision>
    <collision>
      <origin xyz="-0.003891 -0.08 0.0"/>
      <geometry>
        <box size="0.02 0.013 0.013"/>
      </geometry>
    </collision>
    <collision>
      <origin xyz="-0.0203895 0.0 0.0"/>
      <geometry>
        <box size="0.013 0.173032  0.013"/>
      </geometry>
    </collision>
  </link>
  <joint name="fridge_door2_joint" type="revolute">
    <origin rpy="0.0 0.0 0.0" xyz="-0.2990897 -0.29725901 -0.63800789"/>
    <parent link="cabinet3"/>
    <child link="fridge_door2"/>
    <axis xyz="0 0 -1"/>
    <limit effort="1000.0" lower="0.0" upper="1.5707963267948966" velocity="1.5707963267948966"/>
  </joint>
  <link name="fridge_door2">
    <visual>
      <geometry>
        <mesh filename="package://iai_apartment/meshes/unreal/SM_Fridge_Door_02.dae"/>
      </geometry>
    </visual>
    <collision>
      <origin xyz="0.297325 0.006948 -0.028308"/>
      <geometry>
        <box size="0.596492 0.018554 0.78594"/>
      </geometry>
    </collision>
    <collision>
      <origin xyz="0.295455 0.03605 0.019366 "/>
      <geometry>
        <box size="0.553734 0.025 0.622332"/>
      </geometry>
    </collision>
  </link>
  <joint name="fridge_door2_handle_joint" type="fixed">
    <origin rpy="0.0 0.0 1.5707963267948966" xyz="0.46538265 0.00804657 0.28486839"/>
    <parent link="fridge_door2"/>
    <child link="fridge_door2_handle"/>
  </joint>
  <link name="fridge_door2_handle">
    <visual>
      <geometry>
        <mesh filename="package://iai_apartment/meshes/unreal/SM_Kitchen_Handle.dae"/>
      </geometry>
    </visual>
    <collision>
      <origin xyz="-0.003891 0.08 0.0"/>
      <geometry>
        <box size="0.02 0.013 0.013"/>
      </geometry>
    </collision>
    <collision>
      <origin xyz="-0.003891 -0.08 0.0"/>
      <geometry>
        <box size="0.02 0.013 0.013"/>
      </geometry>
    </collision>
    <collision>
      <origin xyz="-0.0203895 0.0 0.0"/>
      <geometry>
        <box size="0.013 0.173032  0.013"/>
      </geometry>
    </collision>
  </link>
  <joint name="fridge_base_joint" type="fixed">
    <origin rpy="0.0 0.0 0.0" xyz="0.00292496 -0.01918092 -0.0816938"/>
    <parent link="cabinet3"/>
    <child link="fridge_base"/>
  </joint>
  <link name="fridge_base">
    <visual>
      <geometry>
        <mesh filename="package://iai_apartment/meshes/unreal/SM_Fridge_Base.dae"/>
      </geometry>
    </visual>
    <collision>
      <origin xyz="0.257778 0.016051 0.0"/>
      <geometry>
        <box size="0.043244 0.483652 1.75881"/>
      </geometry>
    </collision>
    <collision>
      <origin xyz="-0.257778 0.016051 0.0"/>
      <geometry>
        <box size="0.043244 0.483652 1.75881"/>
      </geometry>
    </collision>
    <collision>
      <origin xyz="0.223235 -0.029351 -0.561142"/>
      <geometry>
        <box size="0.024554 0.392848 0.636392"/>
      </geometry>
    </collision>
    <collision>
      <origin xyz="-0.223235 -0.029351 -0.561142"/>
      <geometry>
        <box size="0.024554 0.392848 0.636392"/>
      </geometry>
    </collision>
    <collision>
      <origin xyz="0.0 0.011034 0.855407"/>
      <geometry>
        <box size="0.556434 0.49339 0.047996"/>
      </geometry>
    </collision>
    <collision>
      <origin xyz="0.0 -0.029351 0.839695"/>
      <geometry>
        <box size="0.469566 0.392848 0.07542"/>
      </geometry>
    </collision>
    <collision>
      <origin xyz="0.0 -0.029351 0.224975"/>
      <geometry>
        <box size="0.469566 0.392848 0.025"/>
      </geometry>
    </collision>
    <collision>
      <origin xyz="0.0 -0.029351 -0.18398"/>
      <geometry>
        <box size="0.469566 0.392848 0.11793"/>
      </geometry>
    </collision>
    <collision>
      <origin xyz="0.0 -0.029351 -0.842617"/>
      <geometry>
        <box size="0.469566 0.392848 0.073576"/>
      </geometry>
    </collision>
    <collision>
      <origin xyz="0.0 0.159364 0.339754"/>
      <geometry>
        <box size="0.469566 0.01564 0.929316"/>
      </geometry>
    </collision>
    <collision>
      <origin xyz="0.0 0.199778 -0.524221"/>
      <geometry>
        <box size="0.469566 0.116796 0.56255"/>
      </geometry>
    </collision>
  </link>
  <joint name="fridge_shelf1_joint" type="fixed">
    <origin rpy="0.0 0.0 0.0" xyz="-0.00204316 -0.00102744 0.54545097"/>
    <parent link="fridge_base"/>
    <child link="fridge_shelf1"/>
  </joint>
  <link name="fridge_shelf1">
    <visual>
      <geometry>
        <mesh filename="package://iai_apartment/meshes/unreal/SM_Fridge_Shelf.dae"/>
      </geometry>
    </visual>
    <collision>
      <origin xyz="0.0 0.0 0.0"/>
      <geometry>
        <box size="0.468268 0.267982 0.009088"/>
      </geometry>
    </collision>
  </link>
  <joint name="fridge_shelf2_joint" type="fixed">
    <origin rpy="0.0 0.0 0.0" xyz="-0.00204316 -0.00102744 0.41123558"/>
    <parent link="fridge_base"/>
    <child link="fridge_shelf2"/>
  </joint>
  <link name="fridge_shelf2">
    <visual>
      <geometry>
        <mesh filename="package://iai_apartment/meshes/unreal/SM_Fridge_Shelf.dae"/>
      </geometry>
    </visual>
    <collision>
      <origin xyz="0.0 0.0 0.0"/>
      <geometry>
        <box size="0.468268 0.267982 0.009088"/>
      </geometry>
    </collision>
  </link>
  <joint name="fridge_drawer1_joint" type="prismatic">
    <origin rpy="0.0 0.0 0.0" xyz="-0.00223595 -0.01209006 0.11025719"/>
    <parent link="fridge_base"/>
    <child link="fridge_drawer1"/>
    <axis xyz="0 -1 0"/>
    <limit effort="1000.0" lower="0.0" upper="0.30" velocity="0.5"/>
  </joint>
  <link name="fridge_drawer1">
    <visual>
      <geometry>
        <mesh filename="package://iai_apartment/meshes/unreal/SM_Fridge_Drawer_01.dae"/>
      </geometry>
    </visual>
    <collision>
      <origin xyz="0.0 -0.169309 0.070506"/>
      <geometry>
        <box size="0.454234 0.005 0.023842"/>
      </geometry>
    </collision>
    <collision>
      <origin xyz="0.0 -0.169309 -0.034598"/>
      <geometry>
        <box size="0.454234 0.002896 0.095728"/>
      </geometry>
    </collision>
    <collision>
      <origin xyz="0.0 0.16468 0.0"/>
      <geometry>
        <box size="0.454234 0.004246 0.164152"/>
      </geometry>
    </collision>
    <collision>
      <origin xyz="-0.217307 0.0 0.0"/>
      <geometry>
        <box size="0.01966 0.343522 0.164152"/>
      </geometry>
    </collision>
    <collision>
      <origin xyz="0.217307 0.0 0.0"/>
      <geometry>
        <box size="0.01966 0.343522 0.164152"/>
      </geometry>
    </collision>
    <collision>
      <origin xyz="0.0 0.0 -0.080999"/>
      <geometry>
        <box size="0.454234 0.343522 0.002744"/>
      </geometry>
    </collision>
  </link>
  <joint name="fridge_drawer2_joint" type="prismatic">
    <origin rpy="0.0 0.0 0.0" xyz="0.00198811 -0.01548341 -0.0496125"/>
    <parent link="fridge_base"/>
    <child link="fridge_drawer2"/>
    <axis xyz="0 -1 0"/>
    <limit effort="1000.0" lower="0.0" upper="0.30" velocity="0.5"/>
  </joint>
  <link name="fridge_drawer2">
    <visual>
      <geometry>
        <mesh filename="package://iai_apartment/meshes/unreal/SM_Fridge_Drawer_02.dae"/>
      </geometry>
    </visual>
    <collision>
      <origin xyz="0.0 -0.169309 0.057007"/>
      <geometry>
        <box size="0.454234 0.005 0.023602"/>
      </geometry>
    </collision>
    <collision>
      <origin xyz="0.0 -0.169309 -0.036775"/>
      <geometry>
        <box size="0.454234 0.002896 0.064222"/>
      </geometry>
    </collision>
    <collision>
      <origin xyz="0.0 0.16468 0.0"/>
      <geometry>
        <box size="0.454234 0.004246 0.137882"/>
      </geometry>
    </collision>
    <collision>
      <origin xyz="-0.217307 0.0 0.0"/>
      <geometry>
        <box size="0.01966 0.343522 0.137882"/>
      </geometry>
    </collision>
    <collision>
      <origin xyz="0.217307 0.0 0.0"/>
      <geometry>
        <box size="0.01966 0.343522 0.137882"/>
      </geometry>
    </collision>
    <collision>
      <origin xyz="0.0 0.0 -0.066161"/>
      <geometry>
        <box size="0.454234 0.343522 0.002744"/>
      </geometry>
    </collision>
  </link>
  <joint name="fridge_drawer3_joint" type="prismatic">
    <origin rpy="0.0 0.0 0.0" xyz="-0.00251899 -0.03265699 -0.3561763"/>
    <parent link="fridge_base"/>
    <child link="fridge_drawer3"/>
    <axis xyz="0 -1 0"/>
    <limit effort="1000.0" lower="0.0" upper="0.30" velocity="0.5"/>
  </joint>
  <link name="fridge_drawer3">
    <visual>
      <geometry>
        <mesh filename="package://iai_apartment/meshes/unreal/SM_Fridge_Drawer_03.dae"/>
      </geometry>
    </visual>
    <collision>
      <origin xyz="0.0 -0.165482 0.083453"/>
      <geometry>
        <box size="0.408956 0.002 0.024924"/>
      </geometry>
    </collision>
    <collision>
      <origin xyz="0.0 -0.165482 -0.037113"/>
      <geometry>
        <box size="0.408956 0.002 0.11774"/>
      </geometry>
    </collision>
    <collision>
      <origin xyz="0.0 0.154928 0.0"/>
      <geometry>
        <box size="0.408956 0.00311 0.19183"/>
      </geometry>
    </collision>
    <collision>
      <origin xyz="-0.197083 -0.004962 0.0"/>
      <geometry>
        <box size="0.01464 0.32289 0.19183"/>
      </geometry>
    </collision>
    <collision>
      <origin xyz="0.197083 -0.004962 0.0"/>
      <geometry>
        <box size="0.01464 0.32289 0.19183"/>
      </geometry>
    </collision>
    <collision>
      <origin xyz="0.0 -0.004962 -0.095072"/>
      <geometry>
        <box size="0.408956 0.32289 0.001822"/>
      </geometry>
    </collision>
  </link>
  <joint name="fridge_drawer4_joint" type="prismatic">
    <origin rpy="0.0 0.0 0.0" xyz="-0.00508168 -0.02885223 -0.53299805"/>
    <parent link="fridge_base"/>
    <child link="fridge_drawer4"/>
    <axis xyz="0 -1 0"/>
    <limit effort="1000.0" lower="0.0" upper="0.30" velocity="0.5"/>
  </joint>
  <link name="fridge_drawer4">
    <visual>
      <geometry>
        <mesh filename="package://iai_apartment/meshes/unreal/SM_Fridge_Drawer_04.dae"/>
      </geometry>
    </visual>
    <collision>
      <origin xyz="0.0 -0.165482 0.063456"/>
      <geometry>
        <box size="0.408956 0.002 0.024924"/>
      </geometry>
    </collision>
    <collision>
      <origin xyz="0.0 -0.165482 -0.035978"/>
      <geometry>
        <box size="0.408956 0.002 0.08"/>
      </geometry>
    </collision>
    <collision>
      <origin xyz="0.0 0.155483 0.0"/>
      <geometry>
        <box size="0.408956 0.002 0.151834"/>
      </geometry>
    </collision>
    <collision>
      <origin xyz="-0.196311 0.0 0.0"/>
      <geometry>
        <box size="0.016 0.332816 0.151834"/>
      </geometry>
    </collision>
    <collision>
      <origin xyz="0.196311 0.0 0.0"/>
      <geometry>
        <box size="0.016 0.332816 0.151834"/>
      </geometry>
    </collision>
    <collision>
      <origin xyz="0.0 0.0 -0.074992"/>
      <geometry>
        <box size="0.408956 0.332816 0.002"/>
      </geometry>
    </collision>
  </link>
  <joint name="fridge_drawer5_joint" type="prismatic">
    <origin rpy="0.0 0.0 0.0" xyz="0.0 -0.064807663 -0.712787175"/>
    <parent link="fridge_base"/>
    <child link="fridge_drawer5"/>
    <axis xyz="0 -1 0"/>
    <limit effort="1000.0" lower="0.0" upper="0.30" velocity="0.5"/>
  </joint>
  <link name="fridge_drawer5">
    <visual>
      <geometry>
        <mesh filename="package://iai_apartment/meshes/unreal/SM_Fridge_Drawer_05.dae"/>
      </geometry>
    </visual>
    <collision>
      <origin xyz="0.0 -0.120488 0.08099"/>
      <geometry>
        <box size="0.408808 0.002 0.024998"/>
      </geometry>
    </collision>
    <collision>
      <origin xyz="0.0 -0.118669 -0.03813"/>
      <geometry>
        <box size="0.408808 0.002 0.110706"/>
      </geometry>
    </collision>
    <collision>
      <origin xyz="0.0 0.108269 0.0"/>
      <geometry>
        <box size="0.408808 0.006434 0.151834"/>
      </geometry>
    </collision>
    <collision>
      <origin xyz="-0.196942 0.0 0.0"/>
      <geometry>
        <box size="0.014922 0.240842 0.151834"/>
      </geometry>
    </collision>
    <collision>
      <origin xyz="0.196942 0.0 0.0"/>
      <geometry>
        <box size="0.014922 0.240842 0.151834"/>
      </geometry>
    </collision>
    <collision>
      <origin xyz="0.0 0.0 -0.09249"/>
      <geometry>
        <box size="0.408808 0.240842 0.002"/>
      </geometry>
    </collision>
  </link>
  <!-- Cabinet4 -->
  <joint name="cabinet4_joint" type="fixed">
    <origin rpy="0.0 0.0 1.5707963267948966" xyz="0.18224365 3.29388123 1.82711395"/>
    <parent link="kitchen1_root"/>
    <child link="cabinet4"/>
  </joint>
  <link name="cabinet4">
    <visual>
      <geometry>
        <mesh filename="package://iai_apartment/meshes/unreal/SM_Kitchen_04_Base.dae"/>
      </geometry>
    </visual>
    <collision>
      <origin xyz="-0.010048 0.168984 0.0"/>
      <geometry>
        <box size="0.967896 0.01 0.76582"/>
      </geometry>
    </collision>
    <collision>
      <origin xyz="-0.501898 0.01 0.0"/>
      <geometry>
        <box size="0.016 0.349962 0.797816"/>
      </geometry>
    </collision>
    <collision>
      <origin xyz="0.481997 0.01 0.0"/>
      <geometry>
        <box size="0.016 0.349962 0.797816"/>
      </geometry>
    </collision>
    <collision>
      <origin xyz="0.5 0.0 0.0"/>
      <geometry>
        <box size="0.02 0.369738 0.797816"/>
      </geometry>
    </collision>
    <collision>
      <origin xyz="-0.010048 0.004 0.390908"/>
      <geometry>
        <box size="0.967896 0.337962 0.016"/>
      </geometry>
    </collision>
    <collision>
      <origin xyz="-0.010048 0.004 -0.391007"/>
      <geometry>
        <box size="0.967896 0.337962 0.016"/>
      </geometry>
    </collision>
  </link>
  <joint name="cabinet4_door1_joint" type="fixed">
    <origin rpy="0.0 0.0 0.0" xyz="-0.00837158 -0.17226107 0.19916718"/>
    <parent link="cabinet4"/>
    <child link="cabinet4_door1"/>
  </joint>
  <link name="cabinet4_door1">
    <visual>
      <geometry>
        <mesh filename="package://iai_apartment/meshes/unreal/SM_Kitchen_04_Door_01.dae"/>
      </geometry>
    </visual>
    <collision>
      <origin xyz="0.0 -0.002895 0.0"/>
      <geometry>
        <box size="0.994892 0.019 0.395736"/>
      </geometry>
    </collision>
  </link>
  <joint name="cabinet4_door2_joint" type="fixed">
    <origin rpy="0.0 0.0 0.0" xyz="-0.0093109 -0.15042921 -0.19994873"/>
    <parent link="cabinet4"/>
    <child link="cabinet4_door2"/>
  </joint>
  <link name="cabinet4_door2">
    <visual>
      <geometry>
        <mesh filename="package://iai_apartment/meshes/unreal/SM_Kitchen_04_Door_02.dae"/>
      </geometry>
    </visual>
    <collision>
      <origin xyz="0.0 -0.025359 0.0"/>
      <geometry>
        <box size="0.994892 0.019 0.395736"/>
      </geometry>
    </collision>
  </link>
  <joint name="cabinet4_door2_handle_joint" type="fixed">
    <origin rpy="0.0 0.0 1.5707963267948966" xyz="0.01415195 -0.04103859 -0.13357088"/>
    <parent link="cabinet4_door2"/>
    <child link="cabinet4_door2_handle"/>
  </joint>
  <link name="cabinet4_door2_handle">
    <visual>
      <geometry>
        <mesh filename="package://iai_apartment/meshes/unreal/SM_Kitchen_Handle.dae"/>
      </geometry>
    </visual>
    <collision>
      <origin xyz="-0.003891 0.08 0.0"/>
      <geometry>
        <box size="0.02 0.013 0.013"/>
      </geometry>
    </collision>
    <collision>
      <origin xyz="-0.003891 -0.08 0.0"/>
      <geometry>
        <box size="0.02 0.013 0.013"/>
      </geometry>
    </collision>
    <collision>
      <origin xyz="-0.0203895 0.0 0.0"/>
      <geometry>
        <box size="0.013 0.173032  0.013"/>
      </geometry>
    </collision>
  </link>
  <joint name="cabinet4_shelf1_joint" type="fixed">
    <origin rpy="0.0 0.0 3.141592653589793" xyz="-0.01016479 0.00833792 0.12500641"/>
    <parent link="cabinet4"/>
    <child link="cabinet4_shelf1"/>
  </joint>
  <link name="cabinet4_shelf1">
    <visual>
      <geometry>
        <mesh filename="package://iai_apartment/meshes/unreal/SM_Kitchen_04_Shelf.dae"/>
      </geometry>
    </visual>
    <collision>
      <origin xyz="0.0 0.0 0.0"/>
      <geometry>
        <box size="0.967896 0.307078 0.008084"/>
      </geometry>
    </collision>
  </link>
  <joint name="cabinet4_shelf2_joint" type="fixed">
    <origin rpy="0.0 0.0 3.141592653589793" xyz="-0.01016479 0.00833792 -0.09840179"/>
    <parent link="cabinet4"/>
    <child link="cabinet4_shelf2"/>
  </joint>
  <link name="cabinet4_shelf2">
    <visual>
      <geometry>
        <mesh filename="package://iai_apartment/meshes/unreal/SM_Kitchen_04_Shelf.dae"/>
      </geometry>
    </visual>
    <collision>
      <origin xyz="0.0 0.0 0.0"/>
      <geometry>
        <box size="0.967896 0.307078 0.008084"/>
      </geometry>
    </collision>
  </link>
  <!-- Cabinet5 -->
  <joint name="counter_wall_joint" type="fixed">
    <origin rpy="0.0 0.0 -1.5707963267948966" xyz="0.28142776 3.29494293 0.90892097"/>
    <parent link="kitchen1_root"/>
    <child link="counter_wall"/>
  </joint>
  <link name="counter_wall">
    <visual>
      <geometry>
        <mesh filename="package://iai_apartment/meshes/unreal/SM_Counter_Wall.dae"/>
      </geometry>
    </visual>
    <collision>
      <origin xyz="0.0 0.0 0.0"/>
      <geometry>
        <box size="1.031064 0.599 0.026778"/>
      </geometry>
    </collision>
  </link>
  <joint name="cabinet5_joint" type="fixed">
    <origin rpy="0.0 0.0 1.5707963267948966" xyz="0.27476608 3.08411682 0.49420666"/>
    <parent link="kitchen1_root"/>
    <child link="cabinet5"/>
  </joint>
  <link name="cabinet5">
    <visual>
      <geometry>
        <mesh filename="package://iai_apartment/meshes/unreal/SM_Kitchen_05_Base.dae"/>
      </geometry>
    </visual>
    <collision>
      <origin xyz="-0.291968 0.0 0.0"/>
      <geometry>
        <box size="0.016 0.55452 0.798012"/>
      </geometry>
    </collision>
    <collision>
      <origin xyz="0.291968 0.0 0.0"/>
      <geometry>
        <box size="0.016 0.55452 0.798012"/>
      </geometry>
    </collision>
    <collision>
      <origin xyz="0.0 0.0 -0.391006"/>
      <geometry>
        <box size="0.568134 0.55452 0.016"/>
      </geometry>
    </collision>
    <collision>
      <origin xyz="0.0 0.217476 0.390909"/>
      <geometry>
        <box size="0.568134 0.08 0.016"/>
      </geometry>
    </collision>
    <collision>
      <origin xyz="0.0 0.261473 0.0"/>
      <geometry>
        <box size="0.568134 0.008 0.76582"/>
      </geometry>
    </collision>
  </link>
  <joint name="cabinet5_drawer1_joint" type="prismatic">
    <origin rpy="0.0 0.0 0.0" xyz="0.00100026 -0.05262699 0.33177837"/>
    <parent link="cabinet5"/>
    <child link="cabinet5_drawer1"/>
    <axis xyz="0 -1 0"/>
    <limit effort="1000.0" lower="0.0" upper="0.45" velocity="0.5"/>
  </joint>
  <link name="cabinet5_drawer1">
    <visual>
      <geometry>
        <mesh filename="package://iai_apartment/meshes/unreal/SM_Kitchen_05_Drawer_01.dae"/>
      </geometry>
    </visual>
    <collision>
      <origin xyz="-0.270267 0.021031 -0.01336"/>
      <geometry>
        <box size="0.016 0.491014 0.085266"/>
      </geometry>
    </collision>
    <collision>
      <origin xyz="0.270267 0.021031 -0.01336"/>
      <geometry>
        <box size="0.016 0.491014 0.085266"/>
      </geometry>
    </collision>
    <collision>
      <origin xyz="0.0 -0.233977 0.0"/>
      <geometry>
        <box size="0.596936 0.019 0.129986"/>
      </geometry>
    </collision>
    <collision>
      <origin xyz="0.0 0.260372 -0.01336"/>
      <geometry>
        <box size="0.539608 0.016 0.085266"/>
      </geometry>
    </collision>
    <collision>
      <origin xyz="0.0 0.021031 -0.047595"/>
      <geometry>
        <box size="0.539608 0.491014 0.015"/>
      </geometry>
    </collision>
  </link>
  <joint name="cabinet5_drawer1_handle_joint" type="fixed">
    <origin rpy="0.0 0.0 1.5707963267948966" xyz="-0.00142363 -0.24980946 0.01676949"/>
    <parent link="cabinet5_drawer1"/>
    <child link="cabinet5_drawer1_handle"/>
  </joint>
  <link name="cabinet5_drawer1_handle">
    <visual>
      <geometry>
        <mesh filename="package://iai_apartment/meshes/unreal/SM_Kitchen_Handle.dae"/>
      </geometry>
    </visual>
    <collision>
      <origin xyz="-0.003891 0.08 0.0"/>
      <geometry>
        <box size="0.02 0.013 0.013"/>
      </geometry>
    </collision>
    <collision>
      <origin xyz="-0.003891 -0.08 0.0"/>
      <geometry>
        <box size="0.02 0.013 0.013"/>
      </geometry>
    </collision>
    <collision>
      <origin xyz="-0.0203895 0.0 0.0"/>
      <geometry>
        <box size="0.013 0.173032  0.013"/>
      </geometry>
    </collision>
  </link>
  <joint name="cabinet5_drawer2_joint" type="prismatic">
    <origin rpy="0.0 0.0 0.0" xyz="0.00079152 -0.05303764 0.13372459"/>
    <parent link="cabinet5"/>
    <child link="cabinet5_drawer2"/>
    <axis xyz="0 -1 0"/>
    <limit effort="1000.0" lower="0.0" upper="0.45" velocity="0.5"/>
  </joint>
  <link name="cabinet5_drawer2">
    <visual>
      <geometry>
        <mesh filename="package://iai_apartment/meshes/unreal/SM_Kitchen_05_Drawer_02.dae"/>
      </geometry>
    </visual>
    <collision>
      <origin xyz="-0.270267 0.021031 0.041246"/>
      <geometry>
        <box size="0.016 0.491014 0.023298"/>
      </geometry>
    </collision>
    <collision>
      <origin xyz="0.270267 0.021031 0.041246"/>
      <geometry>
        <box size="0.016 0.491014 0.023298"/>
      </geometry>
    </collision>
    <collision>
      <origin xyz="-0.270267 0.021031 -0.078968"/>
      <geometry>
        <box size="0.016 0.491014 0.083496"/>
      </geometry>
    </collision>
    <collision>
      <origin xyz="0.270267 0.021031 -0.078968"/>
      <geometry>
        <box size="0.016 0.491014 0.083496"/>
      </geometry>
    </collision>
    <collision>
      <origin xyz="0.0 -0.233977 0.0"/>
      <geometry>
        <box size="0.596936 0.019 0.26275"/>
      </geometry>
    </collision>
    <collision>
      <origin xyz="0.0 0.260372 -0.037996"/>
      <geometry>
        <box size="0.539608 0.016 0.168982"/>
      </geometry>
    </collision>
    <collision>
      <origin xyz="0.0 0.021031 -0.113735"/>
      <geometry>
        <box size="0.539608 0.491014 0.016"/>
      </geometry>
    </collision>
  </link>
  <joint name="cabinet5_drawer2_handle_joint" type="fixed">
    <origin rpy="0.0 0.0 1.5707963267948966" xyz="-0.00106413 -0.2507106 0.08500843"/>
    <parent link="cabinet5_drawer2"/>
    <child link="cabinet5_drawer2_handle"/>
  </joint>
  <link name="cabinet5_drawer2_handle">
    <visual>
      <geometry>
        <mesh filename="package://iai_apartment/meshes/unreal/SM_Kitchen_Handle.dae"/>
      </geometry>
    </visual>
    <collision>
      <origin xyz="-0.003891 0.08 0.0"/>
      <geometry>
        <box size="0.02 0.013 0.013"/>
      </geometry>
    </collision>
    <collision>
      <origin xyz="-0.003891 -0.08 0.0"/>
      <geometry>
        <box size="0.02 0.013 0.013"/>
      </geometry>
    </collision>
    <collision>
      <origin xyz="-0.0203895 0.0 0.0"/>
      <geometry>
        <box size="0.013 0.173032  0.013"/>
      </geometry>
    </collision>
  </link>
  <joint name="cabinet5_drawer3_joint" type="prismatic">
    <origin rpy="0.0 0.0 0.0" xyz="0.00075551 -0.05345088 -0.1956669"/>
    <parent link="cabinet5"/>
    <child link="cabinet5_drawer3"/>
    <axis xyz="0 -1 0"/>
    <limit effort="1000.0" lower="0.0" upper="0.45" velocity="0.5"/>
  </joint>
  <link name="cabinet5_drawer3">
    <visual>
      <geometry>
        <mesh filename="package://iai_apartment/meshes/unreal/SM_Kitchen_05_Drawer_03.dae"/>
      </geometry>
    </visual>
    <collision>
      <origin xyz="-0.270267 0.021031 -0.00926"/>
      <geometry>
        <box size="0.016 0.491014 0.023276"/>
      </geometry>
    </collision>
    <collision>
      <origin xyz="0.270267 0.021031 -0.00926"/>
      <geometry>
        <box size="0.016 0.491014 0.023276"/>
      </geometry>
    </collision>
    <collision>
      <origin xyz="-0.270267 0.021031 -0.129424"/>
      <geometry>
        <box size="0.016 0.491014 0.083422"/>
      </geometry>
    </collision>
    <collision>
      <origin xyz="0.270267 0.021031 -0.129424"/>
      <geometry>
        <box size="0.016 0.491014 0.083422"/>
      </geometry>
    </collision>
    <collision>
      <origin xyz="0.0 -0.233977 0.0"/>
      <geometry>
        <box size="0.596936 0.019 0.395734"/>
      </geometry>
    </collision>
    <collision>
      <origin xyz="0.0 0.260372 -0.088821"/>
      <geometry>
        <box size="0.539608 0.016 0.16821"/>
      </geometry>
    </collision>
    <collision>
      <origin xyz="0.0 0.021031 -0.164582"/>
      <geometry>
        <box size="0.539608 0.491014 0.016"/>
      </geometry>
    </collision>
  </link>
  <joint name="cabinet5_drawer3_handle_joint" type="fixed">
    <origin rpy="0.0 0.0 1.5707963267948966" xyz="-0.00102875 -0.24888186 0.15027037"/>
    <parent link="cabinet5_drawer3"/>
    <child link="cabinet5_drawer3_handle"/>
  </joint>
  <link name="cabinet5_drawer3_handle">
    <visual>
      <geometry>
        <mesh filename="package://iai_apartment/meshes/unreal/SM_Kitchen_Handle.dae"/>
      </geometry>
    </visual>
    <collision>
      <origin xyz="-0.003891 0.08 0.0"/>
      <geometry>
        <box size="0.02 0.013 0.013"/>
      </geometry>
    </collision>
    <collision>
      <origin xyz="-0.003891 -0.08 0.0"/>
      <geometry>
        <box size="0.02 0.013 0.013"/>
      </geometry>
    </collision>
    <collision>
      <origin xyz="-0.0203895 0.0 0.0"/>
      <geometry>
        <box size="0.013 0.173032  0.013"/>
      </geometry>
    </collision>
  </link>
  <!-- Cabinet6 -->
  <joint name="cabinet6_joint" type="fixed">
    <origin rpy="0.0 0.0 1.5707963267948966" xyz="0.27476608 3.5838385 0.49420666"/>
    <parent link="kitchen1_root"/>
    <child link="cabinet6"/>
  </joint>
  <link name="cabinet6">
    <visual>
      <geometry>
        <mesh filename="package://iai_apartment/meshes/unreal/SM_Kitchen_06_Base.dae"/>
      </geometry>
    </visual>
    <collision>
      <origin xyz="-0.191779 0.0 0.0"/>
      <geometry>
        <box size="0.016 0.55452 0.798012"/>
      </geometry>
    </collision>
    <collision>
      <origin xyz="0.191779 0.0 0.0"/>
      <geometry>
        <box size="0.016 0.55452 0.798012"/>
      </geometry>
    </collision>
    <collision>
      <origin xyz="0.0 0.0 -0.391006"/>
      <geometry>
        <box size="0.369666 0.55452 0.016"/>
      </geometry>
    </collision>
    <collision>
      <origin xyz="0.0 0.217476 0.390909"/>
      <geometry>
        <box size="0.369666 0.08 0.016"/>
      </geometry>
    </collision>
    <collision>
      <origin xyz="0.0 0.261473 0.0"/>
      <geometry>
        <box size="0.369666 0.008 0.76582"/>
      </geometry>
    </collision>
  </link>
  <joint name="cabinet6_drawer1_joint" type="prismatic">
    <origin rpy="0.0 0.0 0.0" xyz="0.00032649 -0.05329598 0.33177837"/>
    <parent link="cabinet6"/>
    <child link="cabinet6_drawer1"/>
    <axis xyz="0 -1 0"/>
    <limit effort="1000.0" lower="0.0" upper="0.45" velocity="0.5"/>
  </joint>
  <link name="cabinet6_drawer1">
    <visual>
      <geometry>
        <mesh filename="package://iai_apartment/meshes/unreal/SM_Kitchen_06_Drawer_01.dae"/>
      </geometry>
    </visual>
    <collision>
      <origin xyz="-0.170562 0.021031 -0.01336"/>
      <geometry>
        <box size="0.016 0.491014 0.085266"/>
      </geometry>
    </collision>
    <collision>
      <origin xyz="0.170562 0.021031 -0.01336"/>
      <geometry>
        <box size="0.016 0.491014 0.085266"/>
      </geometry>
    </collision>
    <collision>
      <origin xyz="0.0 -0.233977 0.0"/>
      <geometry>
        <box size="0.397734 0.019 0.129986"/>
      </geometry>
    </collision>
    <collision>
      <origin xyz="0.0 0.260372 -0.01336"/>
      <geometry>
        <box size="0.357644 0.016 0.085266"/>
      </geometry>
    </collision>
    <collision>
      <origin xyz="0.0 0.021031 -0.047595"/>
      <geometry>
        <box size="0.357644 0.491014 0.015"/>
      </geometry>
    </collision>
  </link>
  <joint name="cabinet6_drawer1_handle_joint" type="fixed">
    <origin rpy="0.0 0.0 1.5707963267948966" xyz="0.00124599 -0.24662336 0.0172039"/>
    <parent link="cabinet6_drawer1"/>
    <child link="cabinet6_drawer1_handle"/>
  </joint>
  <link name="cabinet6_drawer1_handle">
    <visual>
      <geometry>
        <mesh filename="package://iai_apartment/meshes/unreal/SM_Kitchen_Handle.dae"/>
      </geometry>
    </visual>
    <collision>
      <origin xyz="-0.003891 0.08 0.0"/>
      <geometry>
        <box size="0.02 0.013 0.013"/>
      </geometry>
    </collision>
    <collision>
      <origin xyz="-0.003891 -0.08 0.0"/>
      <geometry>
        <box size="0.02 0.013 0.013"/>
      </geometry>
    </collision>
    <collision>
      <origin xyz="-0.0203895 0.0 0.0"/>
      <geometry>
        <box size="0.013 0.173032  0.013"/>
      </geometry>
    </collision>
  </link>
  <joint name="cabinet6_drawer2_joint" type="prismatic">
    <origin rpy="0.0 0.0 0.0" xyz="0.00074397 -0.05305687 0.13296879"/>
    <parent link="cabinet6"/>
    <child link="cabinet6_drawer2"/>
    <axis xyz="0 -1 0"/>
    <limit effort="1000.0" lower="0.0" upper="0.45" velocity="0.5"/>
  </joint>
  <link name="cabinet6_drawer2">
    <visual>
      <geometry>
        <mesh filename="package://iai_apartment/meshes/unreal/SM_Kitchen_06_Drawer_02.dae"/>
      </geometry>
    </visual>
    <collision>
      <origin xyz="-0.170562 0.021031 0.041246"/>
      <geometry>
        <box size="0.016 0.491014 0.023298"/>
      </geometry>
    </collision>
    <collision>
      <origin xyz="0.170562 0.021031 0.041246"/>
      <geometry>
        <box size="0.016 0.491014 0.023298"/>
      </geometry>
    </collision>
    <collision>
      <origin xyz="-0.170562 0.021031 -0.078968"/>
      <geometry>
        <box size="0.016 0.491014 0.083496"/>
      </geometry>
    </collision>
    <collision>
      <origin xyz="0.170562 0.021031 -0.078968"/>
      <geometry>
        <box size="0.016 0.491014 0.083496"/>
      </geometry>
    </collision>
    <collision>
      <origin xyz="0.0 -0.233977 0.0"/>
      <geometry>
        <box size="0.397734 0.019 0.26275"/>
      </geometry>
    </collision>
    <collision>
      <origin xyz="0.0 0.260372 -0.037996"/>
      <geometry>
        <box size="0.357644 0.016 0.168982"/>
      </geometry>
    </collision>
    <collision>
      <origin xyz="0.0 0.021031 -0.113735"/>
      <geometry>
        <box size="0.357644 0.491014 0.016"/>
      </geometry>
    </collision>
  </link>
  <joint name="cabinet6_drawer2_handle_joint" type="fixed">
    <origin rpy="0.0 0.0 1.5707963267948966" xyz="0.00397854 -0.24686237 0.08541794"/>
    <parent link="cabinet6_drawer2"/>
    <child link="cabinet6_drawer2_handle"/>
  </joint>
  <link name="cabinet6_drawer2_handle">
    <visual>
      <geometry>
        <mesh filename="package://iai_apartment/meshes/unreal/SM_Kitchen_Handle.dae"/>
      </geometry>
    </visual>
    <collision>
      <origin xyz="-0.003891 0.08 0.0"/>
      <geometry>
        <box size="0.02 0.013 0.013"/>
      </geometry>
    </collision>
    <collision>
      <origin xyz="-0.003891 -0.08 0.0"/>
      <geometry>
        <box size="0.02 0.013 0.013"/>
      </geometry>
    </collision>
    <collision>
      <origin xyz="-0.0203895 0.0 0.0"/>
      <geometry>
        <box size="0.013 0.173032  0.013"/>
      </geometry>
    </collision>
  </link>
  <joint name="cabinet6_drawer3_joint" type="prismatic">
    <origin rpy="0.0 0.0 0.0" xyz="0.00069453 -0.05279762 -0.19690866"/>
    <parent link="cabinet6"/>
    <child link="cabinet6_drawer3"/>
    <axis xyz="0 -1 0"/>
    <limit effort="1000.0" lower="0.0" upper="0.45" velocity="0.5"/>
  </joint>
  <link name="cabinet6_drawer3">
    <visual>
      <geometry>
        <mesh filename="package://iai_apartment/meshes/unreal/SM_Kitchen_06_Drawer_03.dae"/>
      </geometry>
    </visual>
    <collision>
      <origin xyz="-0.170562 0.021031 -0.00926"/>
      <geometry>
        <box size="0.016 0.491014 0.023276"/>
      </geometry>
    </collision>
    <collision>
      <origin xyz="0.170562 0.021031 -0.00926"/>
      <geometry>
        <box size="0.016 0.491014 0.023276"/>
      </geometry>
    </collision>
    <collision>
      <origin xyz="-0.170562 0.021031 -0.129424"/>
      <geometry>
        <box size="0.016 0.491014 0.083422"/>
      </geometry>
    </collision>
    <collision>
      <origin xyz="0.170562 0.021031 -0.129424"/>
      <geometry>
        <box size="0.016 0.491014 0.083422"/>
      </geometry>
    </collision>
    <collision>
      <origin xyz="0.0 -0.233977 0.0"/>
      <geometry>
        <box size="0.397734 0.019 0.395734"/>
      </geometry>
    </collision>
    <collision>
      <origin xyz="0.0 0.260372 -0.088821"/>
      <geometry>
        <box size="0.357644 0.016 0.16821"/>
      </geometry>
    </collision>
    <collision>
      <origin xyz="0.0 0.021031 -0.164582"/>
      <geometry>
        <box size="0.357644 0.491014 0.016"/>
      </geometry>
    </collision>
  </link>
  <joint name="cabinet6_drawer3_handle_joint" type="fixed">
    <origin rpy="0.0 0.0 1.5707963267948966" xyz="0.00402777 -0.24712164 0.15116583"/>
    <parent link="cabinet6_drawer3"/>
    <child link="cabinet6_drawer3_handle"/>
  </joint>
  <link name="cabinet6_drawer3_handle">
    <visual>
      <geometry>
        <mesh filename="package://iai_apartment/meshes/unreal/SM_Kitchen_Handle.dae"/>
      </geometry>
    </visual>
    <collision>
      <origin xyz="-0.003891 0.08 0.0"/>
      <geometry>
        <box size="0.02 0.013 0.013"/>
      </geometry>
    </collision>
    <collision>
      <origin xyz="-0.003891 -0.08 0.0"/>
      <geometry>
        <box size="0.02 0.013 0.013"/>
      </geometry>
    </collision>
    <collision>
      <origin xyz="-0.0203895 0.0 0.0"/>
      <geometry>
        <box size="0.013 0.173032  0.013"/>
      </geometry>
    </collision>
  </link>
  <joint name="island_cover4_joint" type="fixed">
    <origin rpy="0.0 0.0 1.5707963267948966" xyz="0.27259209 3.79515656 0.44601677"/>
    <parent link="kitchen1_root"/>
    <child link="island_cover4"/>
  </joint>
  <!-- Kitchen1 base board, island cover -->
  <joint name="kitchen1_base_board_joint" type="fixed">
    <origin rpy="0.0 0.0 -1.5707963267948966" xyz="0.55976036 2.47825577 0.05168431"/>
    <parent link="kitchen1_root"/>
    <child link="kitchen1_base_board"/>
  </joint>
  <link name="kitchen1_base_board">
    <visual>
      <geometry>
        <mesh filename="package://iai_apartment/meshes/unreal/SM_Kitchen_Base_Board_01.dae"/>
      </geometry>
    </visual>
    <collision>
      <origin xyz="0.0 0.0 0.0"/>
      <geometry>
        <box size="2.60316 0.019778 0.1"/>
      </geometry>
    </collision>
  </link>
  <link name="island_cover4">
    <visual>
      <geometry>
        <mesh filename="package://iai_apartment/meshes/unreal/SM_Kitchen_Island_Cover_04.dae"/>
      </geometry>
    </visual>
    <collision>
      <origin xyz="0.0 0.0 0.0"/>
      <geometry>
        <box size="0.019108 0.592148 0.897013"/>
      </geometry>
    </collision>
  </link>
  <!-- Second part of the kitchen (island) -->
  <joint name="kitchen2_root_joint" type="fixed">
    <origin xyz="0.0 0.0 0.0"/>
    <parent link="kitchen_root"/>
    <child link="kitchen2_root"/>
  </joint>
  <link name="kitchen2_root"/>
  <!-- Counter sink stove -->
  <joint name="counter_sink_stove_joint" type="fixed">
    <origin rpy="0.0 0.0 -1.5707963267948966" xyz="2.65274353 2.70903961 0.46562927"/>
    <parent link="kitchen2_root"/>
    <child link="counter_sink_stove"/>
  </joint>
  <link name="counter_sink_stove">
    <visual>
      <geometry>
        <mesh filename="package://iai_apartment/meshes/unreal/SM_Counter_Sink_Stove.dae"/>
      </geometry>
    </visual>
    <collision>
      <origin xyz="1.5755 0.0 0.0"/>
      <geometry>
        <box size="0.029 1.0 0.934462"/>
      </geometry>
    </collision>
    <collision>
      <origin xyz="0.0 0.262968 0.453637"/>
      <geometry>
        <box size="3.17704 0.475062 0.03"/>
      </geometry>
    </collision>
    <collision>
      <origin xyz="0.0 -0.451058 0.453637"/>
      <geometry>
        <box size="3.17704 0.097634 0.03"/>
      </geometry>
    </collision>
    <collision>
      <origin xyz="-1.22213 0.0 0.453637"/>
      <geometry>
        <box size="0.735422 0.996 0.03"/>
      </geometry>
    </collision>
    <collision>
      <origin xyz="0.560551 0.0 0.453637"/>
      <geometry>
        <box size="2.05608 0.996 0.03"/>
      </geometry>
    </collision>
  </link>
  <joint name="stove_joint" type="fixed">
    <origin rpy="0.0 0.0 0.0" xyz="1.08145462 -0.15655746 0.47160622"/>
    <parent link="counter_sink_stove"/>
    <child link="stove"/>
  </joint>
  <link name="stove">
    <visual>
      <geometry>
        <mesh filename="package://iai_apartment/meshes/unreal/SM_Stove.dae"/>
      </geometry>
    </visual>
    <collision>
      <origin xyz="0.0 0.0 0.0"/>
      <geometry>
        <box size="0.795 0.516 0.004802"/>
      </geometry>
    </collision>
  </link>
  <joint name="counter_sink_joint" type="fixed">
    <origin rpy="0.0 0.0 0.0" xyz="-0.66553391 -0.18887642 0.38240448"/>
    <parent link="counter_sink_stove"/>
    <child link="counter_sink"/>
  </joint>
  <link name="counter_sink">
    <visual>
      <geometry>
        <mesh filename="package://iai_apartment/meshes/unreal/SM_Counter_Sink.dae"/>
      </geometry>
    </visual>
    <collision>
      <origin xyz="0.0 0.18348 0.0"/>
      <geometry>
        <box size="0.404212 0.077992 0.177388"/>
      </geometry>
    </collision>
    <collision>
      <origin xyz="0.0 -0.212477 0.0"/>
      <geometry>
        <box size="0.404212 0.02 0.177388"/>
      </geometry>
    </collision>
    <collision>
      <origin xyz="0.192479 0.0 0.0"/>
      <geometry>
        <box size="0.02 0.444618 0.177388"/>
      </geometry>
    </collision>
    <collision>
      <origin xyz="-0.192479 0.0 0.0"/>
      <geometry>
        <box size="0.02 0.444618 0.177388"/>
      </geometry>
    </collision>
    <collision>
      <origin xyz="0.0 0.0 -0.074992"/>
      <geometry>
        <box size="0.404212 0.444618 0.027402"/>
      </geometry>
    </collision>
  </link>
  <joint name="counter_watertab_joint" type="fixed">
    <origin rpy="0.0 0.0 0.0" xyz="0.01961838 0.07677188 0.2389875"/>
    <parent link="counter_sink"/>
    <child link="counter_watertab"/>
  </joint>
  <link name="counter_watertab">
    <visual>
      <geometry>
        <mesh filename="package://iai_apartment/meshes/unreal/SM_Counter_Watertab.dae"/>
      </geometry>
    </visual>
    <collision>
      <origin xyz="-0.0195 0.113704 -0.11162"/>
      <geometry>
        <cylinder length="0.077478" radius="0.022435"/>
      </geometry>
    </collision>
    <collision>
      <origin xyz="-0.0195 0.113704 0.041404"/>
      <geometry>
        <cylinder length="0.21816" radius="0.014"/>
      </geometry>
    </collision>
    <collision>
      <origin xyz="-0.0195 -0.116237 0.121328"/>
      <geometry>
        <cylinder length="0.007636" radius="0.010966"/>
      </geometry>
    </collision>
    <collision>
      <origin rpy="0.0 1.5707963267948966 0.0" xyz="-0.009 0.113731 -0.073523"/>
      <geometry>
        <cylinder length="0.08899" radius="0.022466"/>
      </geometry>
    </collision>
    <collision>
      <origin xyz="0.035496 0.113738 -0.073492"/>
      <geometry>
        <sphere radius="0.018"/>
      </geometry>
    </collision>
    <collision>
      <origin rpy="1.5707963267948966 0.0 0.0" xyz="-0.019498 -0.00425 0.136485"/>
      <geometry>
        <cylinder length="0.263972" radius="0.014"/>
      </geometry>
    </collision>
  </link>
  <joint name="counter_sink_tap_temperature_joint" type="revolute">
    <origin rpy="0.0 0.0 3.141592653589793" xyz="0.04055276 0.11371069 -0.07370445"/>
    <parent link="counter_watertab"/>
    <child link="counter_sink_tap_switch"/>
    <axis xyz="1 0 0"/>
    <limit effort="1000.0" lower="-1.5707963267948966" upper="1.5707963267948966" velocity="3.141592653589793"/>
  </joint>
  <link name="counter_sink_tap_switch">
    <collision>
      <geometry>
        <box size="0.001 0.001 0.001"/>
      </geometry>
    </collision>
  </link>
  <joint name="counter_sink_switch_joint" type="revolute">
    <origin rpy="0.0 0.0 0.0" xyz="0.0 0.0 0.0"/>
    <parent link="counter_sink_tap_switch"/>
    <child link="counter_sink_tap"/>
    <axis xyz="0 -1 0"/>
    <limit effort="1000.0" lower="0.0" upper="0.39269908169872414" velocity="0.39269908169872414"/>
  </joint>
  <link name="counter_sink_tap">
    <visual>
      <geometry>
        <mesh filename="package://iai_apartment/meshes/unreal/SM_Counter_Sink_Tap.dae"/>
      </geometry>
    </visual>
    <collision>
      <origin rpy="0.0 1.5707963267948966 0.0" xyz="-0.007501 0.0 0.0"/>
      <geometry>
        <cylinder length="0.024394" radius="0.022432"/>
      </geometry>
    </collision>
    <collision>
      <origin xyz="-0.012886 0.0 0.048989"/>
      <geometry>
        <cylinder length="0.055994" radius="0.005"/>
      </geometry>
    </collision>
  </link>
  <!-- Dishwasher -->
  <joint name="dishwasher_joint" type="fixed">
    <origin rpy="0.0 0.0 -1.5707963267948966" xyz="2.32419296 3.96355377 0.16226444"/>
    <parent link="kitchen2_root"/>
    <child link="dishwasher"/>
  </joint>
  <link name="dishwasher">
    <visual>
      <geometry>
        <mesh filename="package://iai_apartment/meshes/unreal/SM_Dishwasher_Base.dae"/>
      </geometry>
    </visual>
    <collision>
      <origin xyz="-0.291193 0.244142 0.25785"/>
      <geometry>
        <box size="0.015448 0.395758 0.841796"/>
      </geometry>
    </collision>
    <collision>
      <origin xyz="0.291193 0.244142 0.25785"/>
      <geometry>
        <box size="0.015448 0.395758 0.841796"/>
      </geometry>
    </collision>
    <collision>
      <origin xyz="-0.291193 -0.018498 0.328806"/>
      <geometry>
        <box size="0.015448 0.129522 0.703882"/>
      </geometry>
    </collision>
    <collision>
      <origin xyz="0.291193 -0.018498 0.328806"/>
      <geometry>
        <box size="0.015448 0.129522 0.703882"/>
      </geometry>
    </collision>
    <collision>
      <origin xyz="0.0 0.439555 0.25785"/>
      <geometry>
        <box size="0.597834 0.004826 0.841796"/>
      </geometry>
    </collision>
    <collision>
      <origin xyz="0.0 0.183466 0.671998"/>
      <geometry>
        <box size="0.597834 0.516974 0.013498"/>
      </geometry>
    </collision>
    <collision>
      <origin xyz="0.0 0.183466 -0.079608"/>
      <geometry>
        <box size="0.597834 0.516974 0.167104"/>
      </geometry>
    </collision>
  </link>
  <joint name="dishwasher_front_joint" type="revolute">
    <origin rpy="0.0 0.0 0.0" xyz="0.00031149 -0.07612121 0.00728645"/>
    <parent link="dishwasher"/>
    <child link="dishwasher_front"/>
    <axis xyz="1 0 0"/>
    <limit effort="1000.0" lower="0.0" upper="1.5707963267948966" velocity="1.5707963267948966"/>
  </joint>
  <link name="dishwasher_front">
    <visual>
      <geometry>
        <mesh filename="package://iai_apartment/meshes/unreal/SM_Dishwasher_Front.dae"/>
      </geometry>
    </visual>
    <collision>
      <origin xyz="0.0 -0.04 0.329015"/>
      <geometry>
        <box size="0.609974 0.018888 0.794358"/>
      </geometry>
    </collision>
    <collision>
      <origin xyz="-0.01 -0.015728 0.334215"/>
      <geometry>
        <box size="0.574938 0.03 0.679206"/>
      </geometry>
    </collision>
  </link>
  <joint name="dishwasher_front_handle_joint" type="fixed">
    <origin rpy="0.0 0.0 1.5707963267948966" xyz="-0.0169432 -0.05493519 0.67884796"/>
    <parent link="dishwasher_front"/>
    <child link="dishwasher_front_handle"/>
  </joint>
  <link name="dishwasher_front_handle">
    <visual>
      <geometry>
        <mesh filename="package://iai_apartment/meshes/unreal/SM_Kitchen_Handle.dae"/>
      </geometry>
    </visual>
    <collision>
      <origin xyz="-0.003891 0.08 0.0"/>
      <geometry>
        <box size="0.02 0.013 0.013"/>
      </geometry>
    </collision>
    <collision>
      <origin xyz="-0.003891 -0.08 0.0"/>
      <geometry>
        <box size="0.02 0.013 0.013"/>
      </geometry>
    </collision>
    <collision>
      <origin xyz="-0.0203895 0.0 0.0"/>
      <geometry>
        <box size="0.013 0.173032  0.013"/>
      </geometry>
    </collision>
  </link>
  <joint name="dishwasher_tray1_joint" type="prismatic">
    <origin rpy="0.0 0.0 0.0" xyz="-0.00735926 0.19401426 0.22713593"/>
    <parent link="dishwasher"/>
    <child link="dishwasher_tray1"/>
    <axis xyz="0 -1 0"/>
    <limit effort="1000.0" lower="0.0" upper="0.5" velocity="0.5"/>
  </joint>
  <link name="dishwasher_tray1">
    <visual>
      <geometry>
        <mesh filename="package://iai_apartment/meshes/unreal/SM_Dishwasher_Tray_01.dae"/>
      </geometry>
    </visual>
    <collision>
      <geometry>
        <mesh filename="package://iai_apartment/meshes/unreal/SM_Dishwasher_Tray_01.stl"/>
      </geometry>
    </collision>
  </link>
  <joint name="dishwasher_tray2_joint" type="prismatic">
    <origin rpy="0.0 0.0 0.0" xyz="-0.00735798 0.17742002 0.40232784"/>
    <parent link="dishwasher"/>
    <child link="dishwasher_tray2"/>
    <axis xyz="0 -1 0"/>
    <limit effort="1000.0" lower="0.0" upper="0.3" velocity="0.3"/>
  </joint>
  <link name="dishwasher_tray2">
    <visual>
      <geometry>
        <mesh filename="package://iai_apartment/meshes/unreal/SM_Dishwasher_Tray_02.dae"/>
      </geometry>
    </visual>
    <collision>
      <geometry>
        <mesh filename="package://iai_apartment/meshes/unreal/SM_Dishwasher_Tray_02.stl"/>
      </geometry>
    </collision>
  </link>
  <joint name="dishwasher_tray3_joint" type="prismatic">
    <origin rpy="0.0 0.0 0.0" xyz="-0.01312525 0.19787212 0.61131351"/>
    <parent link="dishwasher"/>
    <child link="dishwasher_tray3"/>
    <axis xyz="0 -1 0"/>
    <limit effort="1000.0" lower="0.0" upper="0.3" velocity="0.3"/>
  </joint>
  <link name="dishwasher_tray3">
    <visual>
      <geometry>
        <mesh filename="package://iai_apartment/meshes/unreal/SM_Dishwasher_Tray_03.dae"/>
      </geometry>
    </visual>
    <collision>
      <geometry>
        <mesh filename="package://iai_apartment/meshes/unreal/SM_Dishwasher_Tray_03.stl"/>
      </geometry>
    </collision>
  </link>
  <!-- Cabinet8 -->
  <joint name="cabinet8_joint" type="fixed">
    <origin rpy="0.0 0.0 -1.5707963267948966" xyz="2.49268082 3.37232117 0.49448143"/>
    <parent link="kitchen2_root"/>
    <child link="cabinet8"/>
  </joint>
  <link name="cabinet8">
    <visual>
      <geometry>
        <mesh filename="package://iai_apartment/meshes/unreal/SM_Kitchen_08_Sink_Base.dae"/>
      </geometry>
    </visual>
    <collision>
      <origin xyz="-0.291912 0.0 0.0"/>
      <geometry>
        <box size="0.015884 0.55405 0.79779"/>
      </geometry>
    </collision>
    <collision>
      <origin xyz="0.291912 0.0 0.0"/>
      <geometry>
        <box size="0.015884 0.55405 0.79779"/>
      </geometry>
    </collision>
    <collision>
      <origin xyz="0.0 0.26153 0.0"/>
      <geometry>
        <box size="0.568134 0.007888 0.765818"/>
      </geometry>
    </collision>
    <collision>
      <origin xyz="0.0 0.217476 0.39091"/>
      <geometry>
        <box size="0.568134 0.08 0.016"/>
      </geometry>
    </collision>
    <collision>
      <origin xyz="0.0 0.0 -0.391005 "/>
      <geometry>
        <box size="0.568134 0.55405 0.016"/>
      </geometry>
    </collision>
  </link>
  <joint name="sink_drawer_joint" type="prismatic">
    <origin rpy="0.0 0.0 0.0" xyz="-0.00013535 -0.05086624 0.0032"/>
    <parent link="cabinet8"/>
    <child link="sink_drawer"/>
    <axis xyz="0 -1 0"/>
    <limit effort="1000.0" lower="0.0" upper="0.45" velocity="0.45"/>
  </joint>
  <link name="sink_drawer">
    <visual>
      <geometry>
        <mesh filename="package://iai_apartment/meshes/unreal/SM_Kitchen_08_Sink_Drawer_01.dae"/>
      </geometry>
    </visual>
    <collision>
      <origin xyz="0.0 -0.233976 0.0"/>
      <geometry>
        <box size="0.596516 0.018776 0.794026"/>
      </geometry>
    </collision>
    <collision>
      <origin xyz="0.0 0.259483 -0.288887"/>
      <geometry>
        <box size="0.539508 0.018034 0.169484"/>
      </geometry>
    </collision>
    <collision>
      <origin xyz="0.268047 0.025012 -0.08949"/>
      <geometry>
        <box size="0.015 0.498056 0.084"/>
      </geometry>
    </collision>
    <collision>
      <origin xyz="-0.268047 0.025012 -0.08949"/>
      <geometry>
        <box size="0.015 0.498056 0.084"/>
      </geometry>
    </collision>
    <collision>
      <origin xyz="0.268047 0.025012 -0.208727"/>
      <geometry>
        <box size="0.015 0.498056 0.023296"/>
      </geometry>
    </collision>
    <collision>
      <origin xyz="-0.268047 0.025012 -0.208727"/>
      <geometry>
        <box size="0.015 0.498056 0.023296"/>
      </geometry>
    </collision>
    <collision>
      <origin xyz="0.268047 0.025012 -0.33085"/>
      <geometry>
        <box size="0.015 0.498056 0.087218"/>
      </geometry>
    </collision>
    <collision>
      <origin xyz="-0.268047 0.025012 -0.33085"/>
      <geometry>
        <box size="0.015 0.498056 0.087218"/>
      </geometry>
    </collision>
    <collision>
      <origin xyz="0.246033 0.025012 -0.04"/>
      <geometry>
        <box size="0.062024 0.498056 0.016"/>
      </geometry>
    </collision>
    <collision>
      <origin xyz="-0.246033 0.025012 -0.04"/>
      <geometry>
        <box size="0.062024 0.498056 0.016"/>
      </geometry>
    </collision>
    <collision>
      <origin xyz="0.0 -0.213959 -0.04"/>
      <geometry>
        <box size="0.554092 0.021008 0.016"/>
      </geometry>
    </collision>
    <collision>
      <origin xyz="0.0 0.21583 -0.04"/>
      <geometry>
        <box size="0.554092 0.117306 0.016"/>
      </geometry>
    </collision>
    <!-- Trash can 1 -->
    <collision>
      <origin xyz="-0.00535 0.086505 -0.198155 "/>
      <geometry>
        <box size="0.016852 0.149578 0.34661"/>
      </geometry>
    </collision>
    <collision>
      <origin xyz="-0.211412 0.086505 -0.198155"/>
      <geometry>
        <box size="0.016852 0.149578 0.34661"/>
      </geometry>
    </collision>
    <collision>
      <origin xyz="-0.109826 0.152938 -0.198155"/>
      <geometry>
        <box size="0.219652 0.016712 0.34661"/>
      </geometry>
    </collision>
    <collision>
      <origin xyz="-0.109826 0.02 -0.198155"/>
      <geometry>
        <box size="0.219652 0.016712 0.34661"/>
      </geometry>
    </collision>
    <collision>
      <origin xyz="-0.109826 0.086505 -0.372315"/>
      <geometry>
        <box size="0.219652 0.149578 0.0017"/>
      </geometry>
    </collision>
    <!-- Trash can 2 -->
    <collision>
      <origin xyz="0.00535 0.086505 -0.198155 "/>
      <geometry>
        <box size="0.016852 0.149578 0.34661"/>
      </geometry>
    </collision>
    <collision>
      <origin xyz="0.211412 0.086505 -0.198155"/>
      <geometry>
        <box size="0.016852 0.149578 0.34661"/>
      </geometry>
    </collision>
    <collision>
      <origin xyz="0.109826 0.152938 -0.198155"/>
      <geometry>
        <box size="0.219652 0.016852 0.34661"/>
      </geometry>
    </collision>
    <collision>
      <origin xyz="0.109826 0.02 -0.198155"/>
      <geometry>
        <box size="0.219652 0.016852 0.34661"/>
      </geometry>
    </collision>
    <collision>
      <origin xyz="0.109826 0.086505 -0.372315"/>
      <geometry>
        <box size="0.219652 0.149578 0.0017"/>
      </geometry>
    </collision>
    <!-- Trash can 3 -->
    <collision>
      <origin xyz="-0.221355 -0.098209 -0.198155"/>
      <geometry>
        <box size="0.016852 0.219458 0.34661"/>
      </geometry>
    </collision>
    <collision>
      <origin xyz="-0.088435 -0.098209 -0.198155"/>
      <geometry>
        <box size="0.016852 0.219458 0.34661"/>
      </geometry>
    </collision>
    <collision>
      <origin xyz="-0.155 0.003041 -0.198155 "/>
      <geometry>
        <box size="0.149382 0.016852 0.34661"/>
      </geometry>
    </collision>
    <collision>
      <origin xyz="-0.155 -0.199821 -0.198155"/>
      <geometry>
        <box size="0.149382 0.016852 0.34661"/>
      </geometry>
    </collision>
    <collision>
      <origin xyz="-0.155 -0.098209 -0.372315"/>
      <geometry>
        <box size="0.149382 0.219458 0.0017"/>
      </geometry>
    </collision>
    <!-- Trash can 4 -->
    <collision>
      <origin xyz="0.221355 -0.098209 -0.198155"/>
      <geometry>
        <box size="0.016852 0.219458 0.34661"/>
      </geometry>
    </collision>
    <collision>
      <origin xyz="-0.071323 -0.098209 -0.198155"/>
      <geometry>
        <box size="0.016852 0.219458 0.34661"/>
      </geometry>
    </collision>
    <collision>
      <origin xyz="0.075302 0.003041 -0.198155 "/>
      <geometry>
        <box size="0.309498 0.016852 0.34661"/>
      </geometry>
    </collision>
    <collision>
      <origin xyz="0.075302 -0.199821 -0.198155"/>
      <geometry>
        <box size="0.309498 0.016852 0.34661"/>
      </geometry>
    </collision>
    <collision>
      <origin xyz="0.075302 -0.098209 -0.372315"/>
      <geometry>
        <box size="0.309498 0.219458 0.0017"/>
      </geometry>
    </collision>
  </link>
  <joint name="sink_drawer_handle_joint" type="fixed">
    <origin rpy="0.0 0.0 1.5707963267948966" xyz="0.00331339 -0.24900223 0.35071747"/>
    <parent link="sink_drawer"/>
    <child link="sink_drawer_handle"/>
  </joint>
  <link name="sink_drawer_handle">
    <visual>
      <geometry>
        <mesh filename="package://iai_apartment/meshes/unreal/SM_Kitchen_Handle.dae"/>
      </geometry>
    </visual>
    <collision>
      <origin xyz="-0.003891 0.08 0.0"/>
      <geometry>
        <box size="0.02 0.013 0.013"/>
      </geometry>
    </collision>
    <collision>
      <origin xyz="-0.003891 -0.08 0.0"/>
      <geometry>
        <box size="0.02 0.013 0.013"/>
      </geometry>
    </collision>
    <collision>
      <origin xyz="-0.0203895 0.0 0.0"/>
      <geometry>
        <box size="0.013 0.173032  0.013"/>
      </geometry>
    </collision>
  </link>
  <!-- Cabinet9 -->
  <joint name="cabinet9_joint" type="fixed">
    <origin rpy="0.0 0.0 -1.5707963267948966" xyz="2.49288239 2.77268799 0.49406776"/>
    <parent link="kitchen2_root"/>
    <child link="cabinet9"/>
  </joint>
  <link name="cabinet9">
    <visual>
      <geometry>
        <mesh filename="package://iai_apartment/meshes/unreal/SM_Kitchen_09_Base.dae"/>
      </geometry>
    </visual>
    <collision>
      <origin xyz="-0.291912 0.0 0.0"/>
      <geometry>
        <box size="0.015884 0.55405 0.79779"/>
      </geometry>
    </collision>
    <collision>
      <origin xyz="0.291912 0.0 0.0"/>
      <geometry>
        <box size="0.015884 0.55405 0.79779"/>
      </geometry>
    </collision>
    <collision>
      <origin xyz="0.0 0.26153 0.0"/>
      <geometry>
        <box size="0.568134 0.007888 0.765818"/>
      </geometry>
    </collision>
    <collision>
      <origin xyz="0.0 0.217476 0.39091"/>
      <geometry>
        <box size="0.568134 0.08 0.016"/>
      </geometry>
    </collision>
    <collision>
      <origin xyz="0.0 0.0 -0.391005 "/>
      <geometry>
        <box size="0.568134 0.55405 0.016"/>
      </geometry>
    </collision>
  </link>
  <joint name="cabinet9_drawer1_joint" type="prismatic">
    <origin rpy="0.0 0.0 0.0" xyz="0.00175364 -0.05079589 0.33208443"/>
    <parent link="cabinet9"/>
    <child link="cabinet9_drawer1"/>
    <axis xyz="0 -1 0"/>
    <limit effort="1000.0" lower="0.0" upper="0.45" velocity="0.5"/>
  </joint>
  <link name="cabinet9_drawer1">
    <visual>
      <geometry>
        <mesh filename="package://iai_apartment/meshes/unreal/SM_Kitchen_09_Drawer_01.dae"/>
      </geometry>
    </visual>
    <collision>
      <origin xyz="-0.270267 0.021031 -0.01336"/>
      <geometry>
        <box size="0.016 0.491014 0.085266"/>
      </geometry>
    </collision>
    <collision>
      <origin xyz="0.270267 0.021031 -0.01336"/>
      <geometry>
        <box size="0.016 0.491014 0.085266"/>
      </geometry>
    </collision>
    <collision>
      <origin xyz="0.0 -0.233977 0.0"/>
      <geometry>
        <box size="0.596936 0.019 0.129986"/>
      </geometry>
    </collision>
    <collision>
      <origin xyz="0.0 0.260372 -0.01336"/>
      <geometry>
        <box size="0.539608 0.016 0.085266"/>
      </geometry>
    </collision>
    <collision>
      <origin xyz="0.0 0.021031 -0.047595"/>
      <geometry>
        <box size="0.539608 0.491014 0.015"/>
      </geometry>
    </collision>
  </link>
  <joint name="cabinet9_drawer1_handle_joint" type="fixed">
    <origin rpy="0.0 0.0 1.5707963267948966" xyz="-0.00142363 -0.24980946 0.01676949"/>
    <parent link="cabinet9_drawer1"/>
    <child link="cabinet9_drawer1_handle"/>
  </joint>
  <link name="cabinet9_drawer1_handle">
    <visual>
      <geometry>
        <mesh filename="package://iai_apartment/meshes/unreal/SM_Kitchen_Handle.dae"/>
      </geometry>
    </visual>
    <collision>
      <origin xyz="-0.003891 0.08 0.0"/>
      <geometry>
        <box size="0.02 0.013 0.013"/>
      </geometry>
    </collision>
    <collision>
      <origin xyz="-0.003891 -0.08 0.0"/>
      <geometry>
        <box size="0.02 0.013 0.013"/>
      </geometry>
    </collision>
    <collision>
      <origin xyz="-0.0203895 0.0 0.0"/>
      <geometry>
        <box size="0.013 0.173032  0.013"/>
      </geometry>
    </collision>
  </link>
  <joint name="cabinet9_drawer2_joint" type="prismatic">
    <origin rpy="0.0 0.0 0.0" xyz="0.00065196 -0.05075302 0.13494465"/>
    <parent link="cabinet9"/>
    <child link="cabinet9_drawer2"/>
    <axis xyz="0 -1 0"/>
    <limit effort="1000.0" lower="0.0" upper="0.45" velocity="0.5"/>
  </joint>
  <link name="cabinet9_drawer2">
    <visual>
      <geometry>
        <mesh filename="package://iai_apartment/meshes/unreal/SM_Kitchen_09_Drawer_02.dae"/>
      </geometry>
    </visual>
    <collision>
      <origin xyz="-0.270267 0.021031 0.041246"/>
      <geometry>
        <box size="0.016 0.491014 0.023298"/>
      </geometry>
    </collision>
    <collision>
      <origin xyz="0.270267 0.021031 0.041246"/>
      <geometry>
        <box size="0.016 0.491014 0.023298"/>
      </geometry>
    </collision>
    <collision>
      <origin xyz="-0.270267 0.021031 -0.078968"/>
      <geometry>
        <box size="0.016 0.491014 0.083496"/>
      </geometry>
    </collision>
    <collision>
      <origin xyz="0.270267 0.021031 -0.078968"/>
      <geometry>
        <box size="0.016 0.491014 0.083496"/>
      </geometry>
    </collision>
    <collision>
      <origin xyz="0.0 -0.233977 0.0"/>
      <geometry>
        <box size="0.596936 0.019 0.26275"/>
      </geometry>
    </collision>
    <collision>
      <origin xyz="0.0 0.260372 -0.037996"/>
      <geometry>
        <box size="0.539608 0.016 0.168982"/>
      </geometry>
    </collision>
    <collision>
      <origin xyz="0.0 0.021031 -0.113735"/>
      <geometry>
        <box size="0.539608 0.491014 0.016"/>
      </geometry>
    </collision>
  </link>
  <joint name="cabinet9_drawer2_handle_joint" type="fixed">
    <origin rpy="0.0 0.0 1.5707963267948966" xyz="-0.00106413 -0.2507106 0.08500843"/>
    <parent link="cabinet9_drawer2"/>
    <child link="cabinet9_drawer2_handle"/>
  </joint>
  <link name="cabinet9_drawer2_handle">
    <visual>
      <geometry>
        <mesh filename="package://iai_apartment/meshes/unreal/SM_Kitchen_Handle.dae"/>
      </geometry>
    </visual>
    <collision>
      <origin xyz="-0.003891 0.08 0.0"/>
      <geometry>
        <box size="0.02 0.013 0.013"/>
      </geometry>
    </collision>
    <collision>
      <origin xyz="-0.003891 -0.08 0.0"/>
      <geometry>
        <box size="0.02 0.013 0.013"/>
      </geometry>
    </collision>
    <collision>
      <origin xyz="-0.0203895 0.0 0.0"/>
      <geometry>
        <box size="0.013 0.173032  0.013"/>
      </geometry>
    </collision>
  </link>
  <joint name="cabinet9_drawer3_joint" type="prismatic">
    <origin rpy="0.0 0.0 0.0" xyz="0.00167063 -0.05045226 -0.19611332"/>
    <parent link="cabinet9"/>
    <child link="cabinet9_drawer3"/>
    <axis xyz="0 -1 0"/>
    <limit effort="1000.0" lower="0.0" upper="0.45" velocity="0.5"/>
  </joint>
  <link name="cabinet9_drawer3">
    <visual>
      <geometry>
        <mesh filename="package://iai_apartment/meshes/unreal/SM_Kitchen_09_Drawer_03.dae"/>
      </geometry>
    </visual>
    <collision>
      <origin xyz="-0.270267 0.021031 -0.00926"/>
      <geometry>
        <box size="0.016 0.491014 0.023276"/>
      </geometry>
    </collision>
    <collision>
      <origin xyz="0.270267 0.021031 -0.00926"/>
      <geometry>
        <box size="0.016 0.491014 0.023276"/>
      </geometry>
    </collision>
    <collision>
      <origin xyz="-0.270267 0.021031 -0.129424"/>
      <geometry>
        <box size="0.016 0.491014 0.083422"/>
      </geometry>
    </collision>
    <collision>
      <origin xyz="0.270267 0.021031 -0.129424"/>
      <geometry>
        <box size="0.016 0.491014 0.083422"/>
      </geometry>
    </collision>
    <collision>
      <origin xyz="0.0 -0.233977 0.0"/>
      <geometry>
        <box size="0.596936 0.019 0.395734"/>
      </geometry>
    </collision>
    <collision>
      <origin xyz="0.0 0.260372 -0.088821"/>
      <geometry>
        <box size="0.539608 0.016 0.16821"/>
      </geometry>
    </collision>
    <collision>
      <origin xyz="0.0 0.021031 -0.164582"/>
      <geometry>
        <box size="0.539608 0.491014 0.016"/>
      </geometry>
    </collision>
  </link>
  <joint name="cabinet9_drawer3_handle_joint" type="fixed">
    <origin rpy="0.0 0.0 1.5707963267948966" xyz="-0.00102875 -0.24888186 0.15027037"/>
    <parent link="cabinet9_drawer3"/>
    <child link="cabinet9_drawer3_handle"/>
  </joint>
  <link name="cabinet9_drawer3_handle">
    <visual>
      <geometry>
        <mesh filename="package://iai_apartment/meshes/unreal/SM_Kitchen_Handle.dae"/>
      </geometry>
    </visual>
    <collision>
      <origin xyz="-0.003891 0.08 0.0"/>
      <geometry>
        <box size="0.02 0.013 0.013"/>
      </geometry>
    </collision>
    <collision>
      <origin xyz="-0.003891 -0.08 0.0"/>
      <geometry>
        <box size="0.02 0.013 0.013"/>
      </geometry>
    </collision>
    <collision>
      <origin xyz="-0.0203895 0.0 0.0"/>
      <geometry>
        <box size="0.013 0.173032  0.013"/>
      </geometry>
    </collision>
  </link>
  <!-- Cabinet10 -->
  <joint name="cabinet10_joint" type="fixed">
    <origin rpy="0.0 0.0 -1.5707963267948966" xyz="2.49299103 2.2719194 0.5011195"/>
    <parent link="kitchen2_root"/>
    <child link="cabinet10"/>
  </joint>
  <link name="cabinet10">
    <visual>
      <geometry>
        <mesh filename="package://iai_apartment/meshes/unreal/SM_Kitchen_10_Base.dae"/>
      </geometry>
    </visual>
    <collision>
      <origin xyz="-0.191779 0.0 0.0"/>
      <geometry>
        <box size="0.016 0.55452 0.798012"/>
      </geometry>
    </collision>
    <collision>
      <origin xyz="0.191779 0.0 0.0"/>
      <geometry>
        <box size="0.016 0.55452 0.798012"/>
      </geometry>
    </collision>
    <collision>
      <origin xyz="0.0 0.0 -0.391006"/>
      <geometry>
        <box size="0.369666 0.55452 0.016"/>
      </geometry>
    </collision>
    <collision>
      <origin xyz="0.0 0.217476 0.390909"/>
      <geometry>
        <box size="0.369666 0.08 0.016"/>
      </geometry>
    </collision>
    <collision>
      <origin xyz="0.0 0.261473 0.0"/>
      <geometry>
        <box size="0.369666 0.008 0.76582"/>
      </geometry>
    </collision>
  </link>
  <joint name="cabinet10_drawer1_joint" type="prismatic">
    <origin rpy="0.0 0.0 0.0" xyz="-0.00062459 -0.05095718 0.32565243"/>
    <parent link="cabinet10"/>
    <child link="cabinet10_drawer1"/>
    <axis xyz="0 -1 0"/>
    <limit effort="1000.0" lower="0.0" upper="0.45" velocity="0.5"/>
  </joint>
  <link name="cabinet10_drawer1">
    <visual>
      <geometry>
        <mesh filename="package://iai_apartment/meshes/unreal/SM_Kitchen_10_Drawer_01.dae"/>
      </geometry>
    </visual>
    <collision>
      <origin xyz="-0.170562 0.021031 -0.01336"/>
      <geometry>
        <box size="0.016 0.491014 0.085266"/>
      </geometry>
    </collision>
    <collision>
      <origin xyz="0.170562 0.021031 -0.01336"/>
      <geometry>
        <box size="0.016 0.491014 0.085266"/>
      </geometry>
    </collision>
    <collision>
      <origin xyz="0.0 -0.233977 0.0"/>
      <geometry>
        <box size="0.397734 0.019 0.129986"/>
      </geometry>
    </collision>
    <collision>
      <origin xyz="0.0 0.260372 -0.01336"/>
      <geometry>
        <box size="0.357644 0.016 0.085266"/>
      </geometry>
    </collision>
    <collision>
      <origin xyz="0.0 0.021031 -0.047595"/>
      <geometry>
        <box size="0.357644 0.491014 0.015"/>
      </geometry>
    </collision>
  </link>
  <joint name="cabinet10_drawer1_handle_joint" type="fixed">
    <origin rpy="0.0 0.0 1.5707963267948966" xyz="0.00124599 -0.24662336 0.0172039"/>
    <parent link="cabinet10_drawer1"/>
    <child link="cabinet10_drawer1_handle"/>
  </joint>
  <link name="cabinet10_drawer1_handle">
    <visual>
      <geometry>
        <mesh filename="package://iai_apartment/meshes/unreal/SM_Kitchen_Handle.dae"/>
      </geometry>
    </visual>
    <collision>
      <origin xyz="-0.003891 0.08 0.0"/>
      <geometry>
        <box size="0.02 0.013 0.013"/>
      </geometry>
    </collision>
    <collision>
      <origin xyz="-0.003891 -0.08 0.0"/>
      <geometry>
        <box size="0.02 0.013 0.013"/>
      </geometry>
    </collision>
    <collision>
      <origin xyz="-0.0203895 0.0 0.0"/>
      <geometry>
        <box size="0.013 0.173032  0.013"/>
      </geometry>
    </collision>
  </link>
  <joint name="cabinet10_drawer2_joint" type="prismatic">
    <origin rpy="0.0 0.0 0.0" xyz="0.00006861 -0.0507138 0.12805202"/>
    <parent link="cabinet10"/>
    <child link="cabinet10_drawer2"/>
    <axis xyz="0 -1 0"/>
    <limit effort="1000.0" lower="0.0" upper="0.45" velocity="0.5"/>
  </joint>
  <link name="cabinet10_drawer2">
    <visual>
      <geometry>
        <mesh filename="package://iai_apartment/meshes/unreal/SM_Kitchen_10_Drawer_02.dae"/>
      </geometry>
    </visual>
    <collision>
      <origin xyz="-0.170562 0.021031 0.041246"/>
      <geometry>
        <box size="0.016 0.491014 0.023298"/>
      </geometry>
    </collision>
    <collision>
      <origin xyz="0.170562 0.021031 0.041246"/>
      <geometry>
        <box size="0.016 0.491014 0.023298"/>
      </geometry>
    </collision>
    <collision>
      <origin xyz="-0.170562 0.021031 -0.078968"/>
      <geometry>
        <box size="0.016 0.491014 0.083496"/>
      </geometry>
    </collision>
    <collision>
      <origin xyz="0.170562 0.021031 -0.078968"/>
      <geometry>
        <box size="0.016 0.491014 0.083496"/>
      </geometry>
    </collision>
    <collision>
      <origin xyz="0.0 -0.233977 0.0"/>
      <geometry>
        <box size="0.397734 0.019 0.26275"/>
      </geometry>
    </collision>
    <collision>
      <origin xyz="0.0 0.260372 -0.037996"/>
      <geometry>
        <box size="0.357644 0.016 0.168982"/>
      </geometry>
    </collision>
    <collision>
      <origin xyz="0.0 0.021031 -0.113735"/>
      <geometry>
        <box size="0.357644 0.491014 0.016"/>
      </geometry>
    </collision>
  </link>
  <joint name="cabinet10_drawer2_handle_joint" type="fixed">
    <origin rpy="0.0 0.0 1.5707963267948966" xyz="0.00397854 -0.24686237 0.08541794"/>
    <parent link="cabinet10_drawer2"/>
    <child link="cabinet10_drawer2_handle"/>
  </joint>
  <link name="cabinet10_drawer2_handle">
    <visual>
      <geometry>
        <mesh filename="package://iai_apartment/meshes/unreal/SM_Kitchen_Handle.dae"/>
      </geometry>
    </visual>
    <collision>
      <origin xyz="-0.003891 0.08 0.0"/>
      <geometry>
        <box size="0.02 0.013 0.013"/>
      </geometry>
    </collision>
    <collision>
      <origin xyz="-0.003891 -0.08 0.0"/>
      <geometry>
        <box size="0.02 0.013 0.013"/>
      </geometry>
    </collision>
    <collision>
      <origin xyz="-0.0203895 0.0 0.0"/>
      <geometry>
        <box size="0.013 0.173032  0.013"/>
      </geometry>
    </collision>
  </link>
  <joint name="cabinet10_drawer3_joint" type="prismatic">
    <origin rpy="0.0 0.0 0.0" xyz="0.00036921 -0.05040313 -0.20396725"/>
    <parent link="cabinet10"/>
    <child link="cabinet10_drawer3"/>
    <axis xyz="0 -1 0"/>
    <limit effort="1000.0" lower="0.0" upper="0.45" velocity="0.5"/>
  </joint>
  <link name="cabinet10_drawer3">
    <visual>
      <geometry>
        <mesh filename="package://iai_apartment/meshes/unreal/SM_Kitchen_10_Drawer_03.dae"/>
      </geometry>
    </visual>
    <collision>
      <origin xyz="-0.170562 0.021031 -0.00926"/>
      <geometry>
        <box size="0.016 0.491014 0.023276"/>
      </geometry>
    </collision>
    <collision>
      <origin xyz="0.170562 0.021031 -0.00926"/>
      <geometry>
        <box size="0.016 0.491014 0.023276"/>
      </geometry>
    </collision>
    <collision>
      <origin xyz="-0.170562 0.021031 -0.129424"/>
      <geometry>
        <box size="0.016 0.491014 0.083422"/>
      </geometry>
    </collision>
    <collision>
      <origin xyz="0.170562 0.021031 -0.129424"/>
      <geometry>
        <box size="0.016 0.491014 0.083422"/>
      </geometry>
    </collision>
    <collision>
      <origin xyz="0.0 -0.233977 0.0"/>
      <geometry>
        <box size="0.397734 0.019 0.395734"/>
      </geometry>
    </collision>
    <collision>
      <origin xyz="0.0 0.260372 -0.088821"/>
      <geometry>
        <box size="0.357644 0.016 0.16821"/>
      </geometry>
    </collision>
    <collision>
      <origin xyz="0.0 0.021031 -0.164582"/>
      <geometry>
        <box size="0.357644 0.491014 0.016"/>
      </geometry>
    </collision>
  </link>
  <joint name="cabinet10_drawer3_handle_joint" type="fixed">
    <origin rpy="0.0 0.0 1.5707963267948966" xyz="0.00402777 -0.24712164 0.15116583"/>
    <parent link="cabinet10_drawer3"/>
    <child link="cabinet10_drawer3_handle"/>
  </joint>
  <link name="cabinet10_drawer3_handle">
    <visual>
      <geometry>
        <mesh filename="package://iai_apartment/meshes/unreal/SM_Kitchen_Handle.dae"/>
      </geometry>
    </visual>
    <collision>
      <origin xyz="-0.003891 0.08 0.0"/>
      <geometry>
        <box size="0.02 0.013 0.013"/>
      </geometry>
    </collision>
    <collision>
      <origin xyz="-0.003891 -0.08 0.0"/>
      <geometry>
        <box size="0.02 0.013 0.013"/>
      </geometry>
    </collision>
    <collision>
      <origin xyz="-0.0203895 0.0 0.0"/>
      <geometry>
        <box size="0.013 0.173032  0.013"/>
      </geometry>
    </collision>
  </link>
  <!-- Cabinet11 -->
  <joint name="cabinet11_joint" type="fixed">
    <origin rpy="0.0 0.0 -1.5707963267948966" xyz="2.49293671 1.62155807 0.50984447"/>
    <parent link="kitchen2_root"/>
    <child link="cabinet11"/>
  </joint>
  <link name="cabinet11">
    <visual>
      <geometry>
        <mesh filename="package://iai_apartment/meshes/unreal/SM_Kitchen_11_Base.dae"/>
      </geometry>
    </visual>
    <collision>
      <origin xyz="-0.441952 0.0 0.0"/>
      <geometry>
        <box size="0.016 0.55452 0.798012"/>
      </geometry>
    </collision>
    <collision>
      <origin xyz="0.441952 0.0 0.0"/>
      <geometry>
        <box size="0.016 0.55452 0.798012"/>
      </geometry>
    </collision>
    <collision>
      <origin xyz="0.0 0.0 -0.391006"/>
      <geometry>
        <box size="0.86788 0.55452 0.016"/>
      </geometry>
    </collision>
    <collision>
      <origin xyz="0.0 0.217476 0.390909"/>
      <geometry>
        <box size="0.86788 0.08 0.016"/>
      </geometry>
    </collision>
    <collision>
      <origin xyz="0.0 0.261473 0.0"/>
      <geometry>
        <box size="0.86788 0.008 0.76582"/>
      </geometry>
    </collision>
  </link>
  <joint name="cabinet11_drawer1_joint" type="prismatic">
    <origin rpy="0.0 0.0 0.0" xyz="-0.00063939 -0.05082244 0.31816875"/>
    <parent link="cabinet11"/>
    <child link="cabinet11_drawer1"/>
    <axis xyz="0 -1 0"/>
    <limit effort="1000.0" lower="0.0" upper="0.45" velocity="0.5"/>
  </joint>
  <link name="cabinet11_drawer1">
    <visual>
      <geometry>
        <mesh filename="package://iai_apartment/meshes/unreal/SM_Kitchen_11_Drawer_01.dae"/>
      </geometry>
    </visual>
    <collision>
      <origin xyz="-0.418233 0.021031 -0.01336"/>
      <geometry>
        <box size="0.016 0.491014 0.085266"/>
      </geometry>
    </collision>
    <collision>
      <origin xyz="0.418233 0.021031 -0.01336"/>
      <geometry>
        <box size="0.016 0.491014 0.085266"/>
      </geometry>
    </collision>
    <collision>
      <origin xyz="0.0 -0.233977 0.0"/>
      <geometry>
        <box size="0.896682 0.019 0.129986"/>
      </geometry>
    </collision>
    <collision>
      <origin xyz="0.0 0.260372 -0.01336"/>
      <geometry>
        <box size="0.839576 0.016 0.085266"/>
      </geometry>
    </collision>
    <collision>
      <origin xyz="0.0 0.021031 -0.047595"/>
      <geometry>
        <box size="0.839576 0.491014 0.015"/>
      </geometry>
    </collision>
  </link>
  <joint name="cabinet11_drawer1_handle_joint" type="fixed">
    <origin rpy="0.0 0.0 1.5707963267948966" xyz="0.00124599 -0.24662336 0.0172039"/>
    <parent link="cabinet11_drawer1"/>
    <child link="cabinet11_drawer1_handle"/>
  </joint>
  <link name="cabinet11_drawer1_handle">
    <visual>
      <geometry>
        <mesh filename="package://iai_apartment/meshes/unreal/SM_Kitchen_Handle.dae"/>
      </geometry>
    </visual>
    <collision>
      <origin xyz="-0.003891 0.08 0.0"/>
      <geometry>
        <box size="0.02 0.013 0.013"/>
      </geometry>
    </collision>
    <collision>
      <origin xyz="-0.003891 -0.08 0.0"/>
      <geometry>
        <box size="0.02 0.013 0.013"/>
      </geometry>
    </collision>
    <collision>
      <origin xyz="-0.0203895 0.0 0.0"/>
      <geometry>
        <box size="0.013 0.173032  0.013"/>
      </geometry>
    </collision>
  </link>
  <joint name="cabinet11_drawer2_joint" type="prismatic">
    <origin rpy="0.0 0.0 0.0" xyz="-0.0004598 -0.05030883 0.11917843"/>
    <parent link="cabinet11"/>
    <child link="cabinet11_drawer2"/>
    <axis xyz="0 -1 0"/>
    <limit effort="1000.0" lower="0.0" upper="0.45" velocity="0.5"/>
  </joint>
  <link name="cabinet11_drawer2">
    <visual>
      <geometry>
        <mesh filename="package://iai_apartment/meshes/unreal/SM_Kitchen_11_Drawer_02.dae"/>
      </geometry>
    </visual>
    <collision>
      <origin xyz="-0.418233 0.021031 0.041246"/>
      <geometry>
        <box size="0.016 0.491014 0.023298"/>
      </geometry>
    </collision>
    <collision>
      <origin xyz="0.418233 0.021031 0.041246"/>
      <geometry>
        <box size="0.016 0.491014 0.023298"/>
      </geometry>
    </collision>
    <collision>
      <origin xyz="-0.418233 0.021031 -0.078968"/>
      <geometry>
        <box size="0.016 0.491014 0.083496"/>
      </geometry>
    </collision>
    <collision>
      <origin xyz="0.418233 0.021031 -0.078968"/>
      <geometry>
        <box size="0.016 0.491014 0.083496"/>
      </geometry>
    </collision>
    <collision>
      <origin xyz="0.0 -0.233977 0.0"/>
      <geometry>
        <box size="0.896682 0.019 0.26275"/>
      </geometry>
    </collision>
    <collision>
      <origin xyz="0.0 0.260372 -0.037996"/>
      <geometry>
        <box size="0.839576 0.016 0.168982"/>
      </geometry>
    </collision>
    <collision>
      <origin xyz="0.0 0.021031 -0.113735"/>
      <geometry>
        <box size="0.839576 0.491014 0.016"/>
      </geometry>
    </collision>
  </link>
  <joint name="cabinet11_drawer2_handle_joint" type="fixed">
    <origin rpy="0.0 0.0 1.5707963267948966" xyz="0.00397854 -0.24686237 0.08541794"/>
    <parent link="cabinet11_drawer2"/>
    <child link="cabinet11_drawer2_handle"/>
  </joint>
  <link name="cabinet11_drawer2_handle">
    <visual>
      <geometry>
        <mesh filename="package://iai_apartment/meshes/unreal/SM_Kitchen_Handle.dae"/>
      </geometry>
    </visual>
    <collision>
      <origin xyz="-0.003891 0.08 0.0"/>
      <geometry>
        <box size="0.02 0.013 0.013"/>
      </geometry>
    </collision>
    <collision>
      <origin xyz="-0.003891 -0.08 0.0"/>
      <geometry>
        <box size="0.02 0.013 0.013"/>
      </geometry>
    </collision>
    <collision>
      <origin xyz="-0.0203895 0.0 0.0"/>
      <geometry>
        <box size="0.013 0.173032  0.013"/>
      </geometry>
    </collision>
  </link>
  <joint name="cabinet11_drawer3_joint" type="prismatic">
    <origin rpy="0.0 0.0 0.0" xyz="-0.00146352 -0.05077515 -0.21330786"/>
    <parent link="cabinet11"/>
    <child link="cabinet11_drawer3"/>
    <axis xyz="0 -1 0"/>
    <limit effort="1000.0" lower="0.0" upper="0.45" velocity="0.5"/>
  </joint>
  <link name="cabinet11_drawer3">
    <visual>
      <geometry>
        <mesh filename="package://iai_apartment/meshes/unreal/SM_Kitchen_11_Drawer_03.dae"/>
      </geometry>
    </visual>
    <collision>
      <origin xyz="-0.418233 0.021031 -0.00926"/>
      <geometry>
        <box size="0.016 0.491014 0.023276"/>
      </geometry>
    </collision>
    <collision>
      <origin xyz="0.418233 0.021031 -0.00926"/>
      <geometry>
        <box size="0.016 0.491014 0.023276"/>
      </geometry>
    </collision>
    <collision>
      <origin xyz="-0.418233 0.021031 -0.129424"/>
      <geometry>
        <box size="0.016 0.491014 0.083422"/>
      </geometry>
    </collision>
    <collision>
      <origin xyz="0.418233 0.021031 -0.129424"/>
      <geometry>
        <box size="0.016 0.491014 0.083422"/>
      </geometry>
    </collision>
    <collision>
      <origin xyz="0.0 -0.233977 0.0"/>
      <geometry>
        <box size="0.896682 0.019 0.395734"/>
      </geometry>
    </collision>
    <collision>
      <origin xyz="0.0 0.260372 -0.088821"/>
      <geometry>
        <box size="0.839576 0.016 0.16821"/>
      </geometry>
    </collision>
    <collision>
      <origin xyz="0.0 0.021031 -0.164582"/>
      <geometry>
        <box size="0.839576 0.491014 0.016"/>
      </geometry>
    </collision>
  </link>
  <joint name="cabinet11_drawer3_handle_joint" type="fixed">
    <origin rpy="0.0 0.0 1.5707963267948966" xyz="0.00402777 -0.24712164 0.15116583"/>
    <parent link="cabinet11_drawer3"/>
    <child link="cabinet11_drawer3_handle"/>
  </joint>
  <link name="cabinet11_drawer3_handle">
    <visual>
      <geometry>
        <mesh filename="package://iai_apartment/meshes/unreal/SM_Kitchen_Handle.dae"/>
      </geometry>
    </visual>
    <collision>
      <origin xyz="-0.003891 0.08 0.0"/>
      <geometry>
        <box size="0.02 0.013 0.013"/>
      </geometry>
    </collision>
    <collision>
      <origin xyz="-0.003891 -0.08 0.0"/>
      <geometry>
        <box size="0.02 0.013 0.013"/>
      </geometry>
    </collision>
    <collision>
      <origin xyz="-0.0203895 0.0 0.0"/>
      <geometry>
        <box size="0.013 0.173032  0.013"/>
      </geometry>
    </collision>
  </link>
  <!-- Kitchen2 base board, island cover -->
  <joint name="kitchen2_base_board_joint" type="fixed">
    <origin rpy="0.0 0.0 -1.5707963267948966" xyz="2.21094345 2.40967743 0.04963645"/>
    <parent link="kitchen2_root"/>
    <child link="kitchen2_base_board"/>
  </joint>
  <link name="kitchen2_base_board">
    <visual>
      <geometry>
        <mesh filename="package://iai_apartment/meshes/unreal/SM_Kitchen_Base_Board_02.dae"/>
      </geometry>
    </visual>
    <collision>
      <origin xyz="-0.3023 0.0 0.0"/>
      <geometry>
        <box size="3.11248 0.02 0.1"/>
      </geometry>
    </collision>
  </link>
  <joint name="island_cover1_joint" type="fixed">
    <origin rpy="0.0 0.0 -1.5707963267948966" xyz="2.86824768 2.71960388 0.4503175"/>
    <parent link="kitchen2_root"/>
    <child link="island_cover1"/>
  </joint>
  <link name="island_cover1">
    <visual>
      <geometry>
        <mesh filename="package://iai_apartment/meshes/unreal/SM_Kitchen_Island_Cover_01.dae"/>
      </geometry>
    </visual>
    <collision>
      <origin xyz="0.0 0.0 0.0"/>
      <geometry>
        <box size="3.13566 0.01925 0.90361"/>
      </geometry>
    </collision>
  </link>
  <joint name="island_cover3_joint" type="fixed">
    <origin rpy="0.0 0.0 1.5707963267948966" xyz="2.53831085 4.27729736 0.45175999"/>
    <parent link="kitchen2_root"/>
    <child link="island_cover3"/>
  </joint>
  <link name="island_cover3">
    <visual>
      <geometry>
        <mesh filename="package://iai_apartment/meshes/unreal/SM_Kitchen_Island_Cover_03.dae"/>
      </geometry>
    </visual>
    <collision>
      <origin xyz="0.0 0.0 0.0"/>
      <geometry>
        <box size="0.02 0.678888 0.90361"/>
      </geometry>
    </collision>
  </link>
  <joint name="island_cover5_joint" type="fixed">
    <origin rpy="0.0 0.0 1.5707963267948966" xyz="2.53749664 1.16088593 0.44601364"/>
    <parent link="kitchen2_root"/>
    <child link="island_cover5"/>
  </joint>
  <link name="island_cover5">
    <visual>
      <geometry>
        <mesh filename="package://iai_apartment/meshes/unreal/SM_Kitchen_Island_Cover_03.dae"/>
      </geometry>
    </visual>
    <collision>
      <origin xyz="0.0 0.0 0.0"/>
      <geometry>
        <box size="0.02 0.678888 0.90361"/>
      </geometry>
    </collision>
  </link>
</robot>

