<robot xmlns:xacro="http://www.ros.org/wiki/xacro" name="kitchen">

  <!-- Such is life in a kitchen : xacro -->
  <xacro:macro name="kitchen_macro" params="name parent *origin">

    <joint name="${name}" type="fixed">
      <xacro:insert_block name="origin" />
      <parent link="${parent}" />
      <child link="kitchen_root" />
    </joint>
    <link name="kitchen_root" />

    <!-- - - - - - - - - - - - - Cabinets side A - - - - - - - - - -->
    <!-- Cabinet1 -->
    <joint name="cabinet1_joint" type="fixed">
      <origin xyz="0.28463219 1.46675873 1.11440605" rpy="0.0 0.0 ${pi/2}" />
      <parent link="kitchen_root" />
      <child link="cabinet1" />
    </joint>

    <link name="cabinet1">
      <visual>
        <geometry>
          <mesh filename="package://iai_apartment/meshes/unreal/SM_Kitchen_01_Base.dae" />
        </geometry>
      </visual>
      <collision>
        <origin xyz="0.3 0.010499 0.05" />
        <geometry>
          <box size="0.019 0.55494 2.12778" />
        </geometry>
      </collision>
      <collision>
        <origin xyz="-0.280469 0.010499 0.05" />
        <geometry>
          <box size="0.019 0.55494 2.12778" />
        </geometry>
      </collision>
      <collision>
        <origin xyz="0.009901 0.271973 0.041995" />
        <geometry>
          <box size="0.561938 0.008 2.11178" />
        </geometry>
      </collision>
      <collision>
        <origin xyz="-0.299967 0.0 0.0" />
        <geometry>
          <box size="0.02092 0.575938 2.22776" />
        </geometry>
      </collision>
      <collision>
        <origin xyz="0.009901 -0.254976 1.06578" />
        <geometry>
          <box size="0.561938 0.016 0.064" />
        </geometry>
      </collision>
      <collision>
        <origin xyz="0.009901 0.0055 1.10578" />
        <geometry>
          <box size="0.561938 0.540942 0.016" />
        </geometry>
      </collision>
      <collision>
        <origin xyz="0.009901 0.0005 0.249501" />
        <geometry>
          <box size="0.561938 0.540942 0.015" />
        </geometry>
      </collision>
      <collision>
        <origin xyz="0.009901 0.0005 -0.361161 " />
        <geometry>
          <box size="0.561938 0.534942 0.015" />
        </geometry>
      </collision>
    </link>

    <joint name="cabinet1_door_joint" type="revolute">
      <origin xyz="-0.274 -0.280 0.677" rpy="0.0 0.0 0.0" />
      <parent link="cabinet1" />
      <child link="cabinet1_door" />
      <axis xyz="0 0 1" />
      <limit effort="1000.0" lower="-${pi/2}" upper="0.0" velocity="${pi/2}" />
    </joint>

    <link name="cabinet1_door">
      <visual>
        <geometry>
          <mesh filename="package://iai_apartment/meshes/unreal/SM_Kitchen_01_Door_01.dae" />
        </geometry>
      </visual>
      <collision>
        <origin xyz="0.285091 -0.00064702 0.0" />
        <geometry>
          <box size="0.596936 0.019 0.86681" />
        </geometry>
      </collision>
    </link>

    <joint name="cabinet1_door_handle_joint" type="fixed">
      <origin xyz="0.46315559 -0.01559982 -0.38983368" rpy="0.0 0.0 0.0" />
      <parent link="cabinet1_door" />
      <child link="cabinet1_door_handle" />
    </joint>

    <link name="cabinet1_door_handle">
      <visual>
        <geometry>
          <mesh filename="package://iai_apartment/meshes/unreal/SM_Kitchen_Handle.dae" />
        </geometry>
      </visual>
      <collision>
        <origin xyz="0.08 -0.003891  0.0" />
        <geometry>
          <box size="0.013 0.02 0.013" />
        </geometry>
      </collision>
      <collision>
        <origin xyz="-0.08 -0.003891  0.0" />
        <geometry>
          <box size="0.013 0.02 0.013" />
        </geometry>
      </collision>
      <collision>
        <origin xyz="0.0 -0.0203895 0.0" />
        <geometry>
          <box size="0.173032 0.013 0.013" />
        </geometry>
      </collision>
    </link>

    <joint name="cabinet1_drawer_middle_joint" type="prismatic">
      <origin xyz="0.01122015 -0.04679018 -0.48658508" rpy="0.0 0.0 0.0" />
      <parent link="cabinet1" />
      <child link="cabinet1_drawer_middle" />
      <axis xyz="0 -1 0" />
      <limit effort="1000.0" lower="0.0" upper="0.45" velocity="0.5" />
    </joint>

    <link name="cabinet1_drawer_middle">
      <visual>
        <geometry>
          <mesh filename="package://iai_apartment/meshes/unreal/SM_Kitchen_01_Drawer_01.dae" />
        </geometry>
      </visual>
      <collision>
        <origin xyz="0.0 -0.233977 0.0" />
        <geometry>
          <box size="0.596936 0.019 0.262972" />
        </geometry>
      </collision>
      <collision>
        <origin xyz="0.26865 0.021336 0.0412455" />
        <geometry>
          <box size="0.0158442 0.4917 0.0223924" />
        </geometry>
      </collision>
      <collision>
        <origin xyz="-0.26865 0.021336 0.0412455" />
        <geometry>
          <box size="0.0158442 0.4917 0.0223924" />
        </geometry>
      </collision>
      <collision>
        <origin xyz="0.26865 0.021336 -0.078968" />
        <geometry>
          <box size="0.0158442 0.4917 0.083496" />
        </geometry>
      </collision>
      <collision>
        <origin xyz="-0.26865 0.021336 -0.0941" />
        <geometry>
          <box size="0.0158442 0.4917 0.053098" />
        </geometry>
      </collision>
      <collision>
        <origin xyz="0.0 0.021399 -0.114232" />
        <geometry>
          <box size="0.52364 0.49156 0.016" />
        </geometry>
      </collision>
      <collision>
        <origin xyz="0.0 0.26 -0.038" />
        <geometry>
          <box size="0.52364 0.01865384 0.16887" />
        </geometry>
      </collision>
    </link>

    <joint name="cabinet1_drawer_middle_handle_joint" type="fixed">
      <origin xyz="0.00091816 -0.24792936 0.08401428" rpy="0.0 0.0 0.0" />
      <parent link="cabinet1_drawer_middle" />
      <child link="cabinet1_drawer_middle_handle" />
    </joint>

    <link name="cabinet1_drawer_middle_handle">
      <visual>
        <geometry>
          <mesh filename="package://iai_apartment/meshes/unreal/SM_Kitchen_Handle.dae" />
        </geometry>
      </visual>
      <collision>
        <origin xyz="0.08 -0.003891  0.0" />
        <geometry>
          <box size="0.013 0.02 0.013" />
        </geometry>
      </collision>
      <collision>
        <origin xyz="-0.08 -0.003891  0.0" />
        <geometry>
          <box size="0.013 0.02 0.013" />
        </geometry>
      </collision>
      <collision>
        <origin xyz="0.0 -0.0203895 0.0" />
        <geometry>
          <box size="0.173032 0.013 0.013" />
        </geometry>
      </collision>
    </link>

    <joint name="cabinet1_drawer_bottom_joint" type="prismatic">
      <origin xyz="0.011 -0.046 -0.816" rpy="0.0 0.0 0.0" />
      <parent link="cabinet1" />
      <child link="cabinet1_drawer_bottom" />
      <axis xyz="0 -1 0" />
      <limit effort="1000.0" lower="0.0" upper="0.45" velocity="0.5" />
    </joint>

    <link name="cabinet1_drawer_bottom">
      <visual>
        <geometry>
          <mesh filename="package://iai_apartment/meshes/unreal/SM_Kitchen_01_Drawer_02.dae" />
        </geometry>
      </visual>
      <collision>
        <origin xyz="0.0 -0.233977 0.0" />
        <geometry>
          <box size="0.596936 0.019 0.39428" />
        </geometry>
      </collision>
      <collision>
        <origin xyz="0.26865 0.021336 -0.0084109" />
        <geometry>
          <box size="0.0158442 0.4917 0.0223924" />
        </geometry>
      </collision>
      <collision>
        <origin xyz="-0.26865 0.021336 -0.0084109" />
        <geometry>
          <box size="0.0158442 0.4917 0.0223924" />
        </geometry>
      </collision>
      <collision>
        <origin xyz="0.26865 0.021336 -0.12854" />
        <geometry>
          <box size="0.0158442 0.4917 0.083502" />
        </geometry>
      </collision>
      <collision>
        <origin xyz="-0.26865 0.021336 -0.12854" />
        <geometry>
          <box size="0.0158442 0.4917 0.083502" />
        </geometry>
      </collision>
      <collision>
        <origin xyz="0.0 0.021399 -0.16226" />
        <geometry>
          <box size="0.52364 0.49156 0.016" />
        </geometry>
      </collision>
      <collision>
        <origin xyz="0.0 0.26 -0.0797358 " />
        <geometry>
          <box size="0.52364 0.01865384 0.1517224" />
        </geometry>
      </collision>
    </link>

    <joint name="cabinet1_drawer_bottom_handle_joint" type="fixed">
      <origin xyz="0.00145845 -0.24909416 0.150606" rpy="0.0 0.0 0.0" />
      <parent link="cabinet1_drawer_bottom" />
      <child link="cabinet1_drawer_bottom_handle" />
    </joint>

    <link name="cabinet1_drawer_bottom_handle">
      <visual>
        <geometry>
          <mesh filename="package://iai_apartment/meshes/unreal/SM_Kitchen_Handle.dae" />
        </geometry>
      </visual>
      <collision>
        <origin xyz="0.08 -0.003891  0.0" />
        <geometry>
          <box size="0.013 0.02 0.013" />
        </geometry>
      </collision>
      <collision>
        <origin xyz="-0.08 -0.003891  0.0" />
        <geometry>
          <box size="0.013 0.02 0.013" />
        </geometry>
      </collision>
      <collision>
        <origin xyz="0.0 -0.0203895 0.0" />
        <geometry>
          <box size="0.173032 0.013 0.013" />
        </geometry>
      </collision>
    </link>

    <joint name="oven_joint" type="fixed">
      <origin xyz="0.0123597 -0.27395857 -0.3426725" rpy="0 0 0" />
      <parent link="cabinet1" />
      <child link="oven" />
    </joint>

    <link name="oven">
      <visual>
        <geometry>
          <mesh filename="package://iai_apartment/meshes/unreal/SM_Oven.dae" />
        </geometry>
      </visual>
      <collision>
        <origin xyz="-0.003055 0.264778 0.50654" />
        <geometry>
          <box size="0.58989 0.545666 0.150842" />
        </geometry>
      </collision>
      <collision>
        <origin xyz="-0.003055 0.264778 0.018039" />
        <geometry>
          <box size="0.58989 0.545666 0.045598" />
        </geometry>
      </collision>
      <collision>
        <origin xyz="-0.2675 0.264778 0.288951" />
        <geometry>
          <box size="0.059 0.545666 0.586022" />
        </geometry>
      </collision>
      <collision>
        <origin xyz="0.264104 0.264778 0.288951" />
        <geometry>
          <box size="0.054902 0.545666 0.586022" />
        </geometry>
      </collision>
      <collision>
        <origin xyz="-0.003055 0.5 0.288951" />
        <geometry>
          <box size="0.58989 0.074784 0.586022" />
        </geometry>
      </collision>
    </link>

    <joint name="oven_door_joint" type="revolute">
      <origin xyz="0.0 0.0 0.0" rpy="0 0 0" />
      <parent link="oven" />
      <child link="oven_door" />
      <axis xyz="1 0 0" />
      <limit effort="1000.0" lower="0.0" upper="${pi/2}" velocity="${pi/2}" />
    </joint>

    <link name="oven_door">
      <visual>
        <geometry>
          <mesh filename="package://iai_apartment/meshes/unreal/SM_Oven_Door.dae" />
        </geometry>
      </visual>
      <collision>
        <origin xyz="-0.002993 0.005395 0.226757" />
        <geometry>
          <box size="0.590588 0.036998 0.471696" />
        </geometry>
      </collision>
    </link>

    <!-- Cabinet2 -->
    <joint name="cabinet2_joint" type="fixed">
      <origin xyz="0.27990936 1.97705429 1.16238914" rpy="0.0 0.0 ${pi/2}" />
      <parent link="kitchen_root" />
      <child link="cabinet2" />
    </joint>

    <link name="cabinet2">
      <visual>
        <geometry>
          <mesh filename="package://iai_apartment/meshes/unreal/SM_Kitchen_02_Base.dae" />
        </geometry>
      </visual>
      <collision>
        <origin xyz="-0.191979 0.005897 0.0" />
        <geometry>
          <box size="0.016 0.554718 2.12768" />
        </geometry>
      </collision>
      <collision>
        <origin xyz="0.191979 0.005897 0.0" />
        <geometry>
          <box size="0.016 0.554718 2.12768" />
        </geometry>
      </collision>
      <collision>
        <origin xyz="0.0 0.005897 1.05584" />
        <geometry>
          <box size="0.367764 0.554718 0.016" />
        </geometry>
      </collision>
      <collision>
        <origin xyz="0.0 0.005897 0.975845" />
        <geometry>
          <box size="0.367764 0.554718 0.016" />
        </geometry>
      </collision>
      <collision>
        <origin xyz="0.0 0.005897 -1.05594" />
        <geometry>
          <box size="0.367764 0.554718 0.016" />
        </geometry>
      </collision>
      <collision>
        <origin xyz="0.0 -0.26039 1.01584" />
        <geometry>
          <box size="0.367764 0.014374 0.063992" />
        </geometry>
      </collision>
      <collision>
        <origin xyz="0.0 0.267372 0.0" />
        <geometry>
          <box size="0.367764 0.008 2.09568" />
        </geometry>
      </collision>
    </link>

    <joint name="cabinet2_shelf_joint" type="fixed">
      <origin xyz="-0.00043732 -0.00337784 0.79036064" rpy="0.0 0.0 0.0" />
      <parent link="cabinet2" />
      <child link="cabinet2_shelf" />
    </joint>

    <link name="cabinet2_shelf">
      <visual>
        <geometry>
          <mesh filename="package://iai_apartment/meshes/unreal/SM_Kitchen_02_Shelf.dae" />
        </geometry>
      </visual>
    </link>

    <joint name="cabinet2_drawer1_joint" type="prismatic">
      <origin xyz="0.00134538 -0.00464775 0.58046211" rpy="0.0 0.0 0.0" />
      <parent link="cabinet2" />
      <child link="cabinet2_drawer1" />
      <axis xyz="0 -1 0" />
      <limit effort="1000.0" lower="0.0" upper="0.45" velocity="0.5" />
    </joint>

    <link name="cabinet2_drawer1">
      <visual>
        <geometry>
          <mesh filename="package://iai_apartment/meshes/unreal/SM_Kitchen_02_Drawer_01.dae" />
        </geometry>
      </visual>
      <collision>
        <origin xyz="0.0 -0.242975 0.0" />
        <geometry>
          <box size="0.361962 0.017 0.10099" />
        </geometry>
      </collision>
      <collision>
        <origin xyz="0.0 0.235441 0.0" />
        <geometry>
          <box size="0.361962 0.016128 0.10099" />
        </geometry>
      </collision>
      <collision>
        <origin xyz="-0.170578 -0.003984 0.0" />
        <geometry>
          <box size="0.016222 0.494978 0.10099" />
        </geometry>
      </collision>
      <collision>
        <origin xyz="0.170578 -0.003984 0.0" />
        <geometry>
          <box size="0.016222 0.494978 0.10099" />
        </geometry>
      </collision>
      <collision>
        <origin xyz="0.0 -0.003984 -0.039746" />
        <geometry>
          <box size="0.361962 0.494978 0.021498" />
        </geometry>
      </collision>
    </link>

    <joint name="cabinet2_drawer2_joint" type="prismatic">
      <origin xyz="0.00134538 -0.00464775 0.4227494" rpy="0.0 0.0 0.0" />
      <parent link="cabinet2" />
      <child link="cabinet2_drawer2" />
      <axis xyz="0 -1 0" />
      <limit effort="1000.0" lower="0.0" upper="0.45" velocity="0.5" />
    </joint>

    <link name="cabinet2_drawer2">
      <visual>
        <geometry>
          <mesh filename="package://iai_apartment/meshes/unreal/SM_Kitchen_02_Drawer_02.dae" />
        </geometry>
      </visual>
      <collision>
        <origin xyz="0.0 -0.242374 -0.042" />
        <geometry>
          <box size="0.361962 0.013796 0.098" />
        </geometry>
      </collision>
      <collision>
        <origin xyz="0.0 -0.242374 0.060843" />
        <geometry>
          <box size="0.361962 0.013796 0.020298" />
        </geometry>
      </collision>
      <collision>
        <origin xyz="-0.148428 -0.242869 0.0" />
        <geometry>
          <box size="0.064882 0.016786 0.18198" />
        </geometry>
      </collision>
      <collision>
        <origin xyz="0.148428 -0.242869 0.0" />
        <geometry>
          <box size="0.064882 0.016786 0.18198" />
        </geometry>
      </collision>
      <collision>
        <origin xyz="0.0 0.235441 0.0" />
        <geometry>
          <box size="0.361962 0.016128 0.181758" />
        </geometry>
      </collision>
      <collision>
        <origin xyz="-0.170578 -0.003984 0.075342" />
        <geometry>
          <box size="0.016222 0.494978 0.023298" />
        </geometry>
      </collision>
      <collision>
        <origin xyz="0.170578 -0.003984 0.075342" />
        <geometry>
          <box size="0.016222 0.494978 0.023298" />
        </geometry>
      </collision>
      <collision>
        <origin xyz="-0.170578 -0.003984 -0.043743" />
        <geometry>
          <box size="0.016222 0.494978 0.087106" />
        </geometry>
      </collision>
      <collision>
        <origin xyz="0.170578 -0.003984 -0.043743" />
        <geometry>
          <box size="0.016222 0.494978 0.087106" />
        </geometry>
      </collision>
      <collision>
        <origin xyz="0.0 -0.003984 -0.080242" />
        <geometry>
          <box size="0.361962 0.494978 0.021498" />
        </geometry>
      </collision>
    </link>

    <joint name="cabinet2_drawer3_joint" type="prismatic">
      <origin xyz="0.00134538 -0.00464775 0.1428965" rpy="0.0 0.0 0.0" />
      <parent link="cabinet2" />
      <child link="cabinet2_drawer3" />
      <axis xyz="0 -1 0" />
      <limit effort="1000.0" lower="0.0" upper="0.45" velocity="0.5" />
    </joint>

    <link name="cabinet2_drawer3">
      <visual>
        <geometry>
          <mesh filename="package://iai_apartment/meshes/unreal/SM_Kitchen_02_Drawer_02.dae" />
        </geometry>
      </visual>
      <collision>
        <origin xyz="0.0 -0.242374 -0.042" />
        <geometry>
          <box size="0.361962 0.013796 0.098" />
        </geometry>
      </collision>
      <collision>
        <origin xyz="0.0 -0.242374 0.060843" />
        <geometry>
          <box size="0.361962 0.013796 0.020298" />
        </geometry>
      </collision>
      <collision>
        <origin xyz="-0.148428 -0.242869 0.0" />
        <geometry>
          <box size="0.064882 0.016786 0.18198" />
        </geometry>
      </collision>
      <collision>
        <origin xyz="0.148428 -0.242869 0.0" />
        <geometry>
          <box size="0.064882 0.016786 0.18198" />
        </geometry>
      </collision>
      <collision>
        <origin xyz="0.0 0.235441 0.0" />
        <geometry>
          <box size="0.361962 0.016128 0.181758" />
        </geometry>
      </collision>
      <collision>
        <origin xyz="-0.170578 -0.003984 0.075342" />
        <geometry>
          <box size="0.016222 0.494978 0.023298" />
        </geometry>
      </collision>
      <collision>
        <origin xyz="0.170578 -0.003984 0.075342" />
        <geometry>
          <box size="0.016222 0.494978 0.023298" />
        </geometry>
      </collision>
      <collision>
        <origin xyz="-0.170578 -0.003984 -0.043743" />
        <geometry>
          <box size="0.016222 0.494978 0.087106" />
        </geometry>
      </collision>
      <collision>
        <origin xyz="0.170578 -0.003984 -0.043743" />
        <geometry>
          <box size="0.016222 0.494978 0.087106" />
        </geometry>
      </collision>
      <collision>
        <origin xyz="0.0 -0.003984 -0.080242" />
        <geometry>
          <box size="0.361962 0.494978 0.021498" />
        </geometry>
      </collision>
    </link>

    <joint name="cabinet2_drawer4_joint" type="prismatic">
      <origin xyz="0.00134538 -0.00464775 -0.24243713" rpy="0.0 0.0 0.0" />
      <parent link="cabinet2" />
      <child link="cabinet2_drawer4" />
      <axis xyz="0 -1 0" />
      <limit effort="1000.0" lower="0.0" upper="0.45" velocity="0.5" />
    </joint>

    <link name="cabinet2_drawer4">
      <visual>
        <geometry>
          <mesh filename="package://iai_apartment/meshes/unreal/SM_Kitchen_02_Drawer_02.dae" />
        </geometry>
      </visual>
      <collision>
        <origin xyz="0.0 -0.242374 -0.042" />
        <geometry>
          <box size="0.361962 0.013796 0.098" />
        </geometry>
      </collision>
      <collision>
        <origin xyz="0.0 -0.242374 0.060843" />
        <geometry>
          <box size="0.361962 0.013796 0.020298" />
        </geometry>
      </collision>
      <collision>
        <origin xyz="-0.148428 -0.242869 0.0" />
        <geometry>
          <box size="0.064882 0.016786 0.18198" />
        </geometry>
      </collision>
      <collision>
        <origin xyz="0.148428 -0.242869 0.0" />
        <geometry>
          <box size="0.064882 0.016786 0.18198" />
        </geometry>
      </collision>
      <collision>
        <origin xyz="0.0 0.235441 0.0" />
        <geometry>
          <box size="0.361962 0.016128 0.181758" />
        </geometry>
      </collision>
      <collision>
        <origin xyz="-0.170578 -0.003984 0.075342" />
        <geometry>
          <box size="0.016222 0.494978 0.023298" />
        </geometry>
      </collision>
      <collision>
        <origin xyz="0.170578 -0.003984 0.075342" />
        <geometry>
          <box size="0.016222 0.494978 0.023298" />
        </geometry>
      </collision>
      <collision>
        <origin xyz="-0.170578 -0.003984 -0.043743" />
        <geometry>
          <box size="0.016222 0.494978 0.087106" />
        </geometry>
      </collision>
      <collision>
        <origin xyz="0.170578 -0.003984 -0.043743" />
        <geometry>
          <box size="0.016222 0.494978 0.087106" />
        </geometry>
      </collision>
      <collision>
        <origin xyz="0.0 -0.003984 -0.080242" />
        <geometry>
          <box size="0.361962 0.494978 0.021498" />
        </geometry>
      </collision>
    </link>

    <joint name="cabinet2_drawer5_joint" type="prismatic">
      <origin xyz="0.00134538 -0.00464775 -0.51809593" rpy="0.0 0.0 0.0" />
      <parent link="cabinet2" />
      <child link="cabinet2_drawer5" />
      <axis xyz="0 -1 0" />
      <limit effort="1000.0" lower="0.0" upper="0.45" velocity="0.5" />
    </joint>

    <link name="cabinet2_drawer5">
      <visual>
        <geometry>
          <mesh filename="package://iai_apartment/meshes/unreal/SM_Kitchen_02_Drawer_02.dae" />
        </geometry>
      </visual>
      <collision>
        <origin xyz="0.0 -0.242374 -0.042" />
        <geometry>
          <box size="0.361962 0.013796 0.098" />
        </geometry>
      </collision>
      <collision>
        <origin xyz="0.0 -0.242374 0.060843" />
        <geometry>
          <box size="0.361962 0.013796 0.020298" />
        </geometry>
      </collision>
      <collision>
        <origin xyz="-0.148428 -0.242869 0.0" />
        <geometry>
          <box size="0.064882 0.016786 0.18198" />
        </geometry>
      </collision>
      <collision>
        <origin xyz="0.148428 -0.242869 0.0" />
        <geometry>
          <box size="0.064882 0.016786 0.18198" />
        </geometry>
      </collision>
      <collision>
        <origin xyz="0.0 0.235441 0.0" />
        <geometry>
          <box size="0.361962 0.016128 0.181758" />
        </geometry>
      </collision>
      <collision>
        <origin xyz="-0.170578 -0.003984 0.075342" />
        <geometry>
          <box size="0.016222 0.494978 0.023298" />
        </geometry>
      </collision>
      <collision>
        <origin xyz="0.170578 -0.003984 0.075342" />
        <geometry>
          <box size="0.016222 0.494978 0.023298" />
        </geometry>
      </collision>
      <collision>
        <origin xyz="-0.170578 -0.003984 -0.043743" />
        <geometry>
          <box size="0.016222 0.494978 0.087106" />
        </geometry>
      </collision>
      <collision>
        <origin xyz="0.170578 -0.003984 -0.043743" />
        <geometry>
          <box size="0.016222 0.494978 0.087106" />
        </geometry>
      </collision>
      <collision>
        <origin xyz="0.0 -0.003984 -0.080242" />
        <geometry>
          <box size="0.361962 0.494978 0.021498" />
        </geometry>
      </collision>
    </link>

    <joint name="cabinet2_drawer6_joint" type="prismatic">
      <origin xyz="0.00134538 -0.00464775 -0.95519203" rpy="0.0 0.0 0.0" />
      <parent link="cabinet2" />
      <child link="cabinet2_drawer6" />
      <axis xyz="0 -1 0" />
      <limit effort="1000.0" lower="0.0" upper="0.45" velocity="0.5" />
    </joint>

    <link name="cabinet2_drawer6">
      <visual>
        <geometry>
          <mesh filename="package://iai_apartment/meshes/unreal/SM_Kitchen_02_Drawer_02.dae" />
        </geometry>
      </visual>
      <collision>
        <origin xyz="0.0 -0.242374 -0.042" />
        <geometry>
          <box size="0.361962 0.013796 0.098" />
        </geometry>
      </collision>
      <collision>
        <origin xyz="0.0 -0.242374 0.060843" />
        <geometry>
          <box size="0.361962 0.013796 0.020298" />
        </geometry>
      </collision>
      <collision>
        <origin xyz="-0.148428 -0.242869 0.0" />
        <geometry>
          <box size="0.064882 0.016786 0.18198" />
        </geometry>
      </collision>
      <collision>
        <origin xyz="0.148428 -0.242869 0.0" />
        <geometry>
          <box size="0.064882 0.016786 0.18198" />
        </geometry>
      </collision>
      <collision>
        <origin xyz="0.0 0.235441 0.0" />
        <geometry>
          <box size="0.361962 0.016128 0.181758" />
        </geometry>
      </collision>
      <collision>
        <origin xyz="-0.170578 -0.003984 0.075342" />
        <geometry>
          <box size="0.016222 0.494978 0.023298" />
        </geometry>
      </collision>
      <collision>
        <origin xyz="0.170578 -0.003984 0.075342" />
        <geometry>
          <box size="0.016222 0.494978 0.023298" />
        </geometry>
      </collision>
      <collision>
        <origin xyz="-0.170578 -0.003984 -0.043743" />
        <geometry>
          <box size="0.016222 0.494978 0.087106" />
        </geometry>
      </collision>
      <collision>
        <origin xyz="0.170578 -0.003984 -0.043743" />
        <geometry>
          <box size="0.016222 0.494978 0.087106" />
        </geometry>
      </collision>
      <collision>
        <origin xyz="0.0 -0.003984 -0.080242" />
        <geometry>
          <box size="0.361962 0.494978 0.021498" />
        </geometry>
      </collision>
    </link>

    <joint name="cabinet2_door_joint" type="revolute">
      <origin xyz="-0.17998091 -0.29852444 0.00105865" rpy="0.0 0.0 0.0" />
      <parent link="cabinet2" />
      <child link="cabinet2_door" />
      <axis xyz="0 0 1" />
      <limit effort="1000.0" lower="-${pi/2}" upper="0.0" velocity="${pi/2}" />
    </joint>

    <link name="cabinet2_door">
      <visual>
        <geometry>
          <mesh filename="package://iai_apartment/meshes/unreal/SM_Kitchen_02_Door.dae" />
        </geometry>
      </visual>
      <collision>
        <origin xyz="0.180483 0.013597 0.0" />
        <geometry>
          <box size="0.395846 0.018678 2.12276" />
        </geometry>
      </collision>
    </link>

    <joint name="cabinet2_door_handle_joint" type="fixed">
      <origin xyz="0.25886013 -0.00184994 -0.05118866" rpy="0.0 0.0 0.0" />
      <parent link="cabinet2_door" />
      <child link="cabinet2_door_handle" />
    </joint>

    <link name="cabinet2_door_handle">
      <visual>
        <geometry>
          <mesh filename="package://iai_apartment/meshes/unreal/SM_Kitchen_Handle.dae" />
        </geometry>
      </visual>
      <collision>
        <origin xyz="0.08 -0.003891  0.0" />
        <geometry>
          <box size="0.013 0.02 0.013" />
        </geometry>
      </collision>
      <collision>
        <origin xyz="-0.08 -0.003891  0.0" />
        <geometry>
          <box size="0.013 0.02 0.013" />
        </geometry>
      </collision>
      <collision>
        <origin xyz="0.0 -0.0203895 0.0" />
        <geometry>
          <box size="0.173032 0.013 0.013" />
        </geometry>
      </collision>
    </link>

    <!-- Cabinet3 -->
    <joint name="cabinet3_joint" type="fixed">
      <origin xyz="0.27498539 2.47989822 1.16287888" rpy="0.0 0.0 ${-pi/2}" />
      <parent link="kitchen_root" />
      <child link="cabinet3" />
    </joint>

    <link name="cabinet3">
      <visual>
        <geometry>
          <mesh filename="package://iai_apartment/meshes/unreal/SM_Kitchen_03_Fridge.dae" />
        </geometry>
      </visual>
      <collision>
        <origin xyz="0.291968 -0.003155 0.0" />
        <geometry>
          <box size="0.02 0.554386 2.12764" />
        </geometry>
      </collision>
      <collision>
        <origin xyz="-0.291968 -0.003155 0.0" />
        <geometry>
          <box size="0.02 0.554386 2.12764" />
        </geometry>
      </collision>
      <collision>
        <origin xyz="0.0 -0.003155 1.05584" />
        <geometry>
          <box size="0.572134 0.554386 0.016" />
        </geometry>
      </collision>
      <collision>
        <origin xyz="0.0 -0.003155 0.895854" />
        <geometry>
          <box size="0.572134 0.554386 0.016" />
        </geometry>
      </collision>
      <collision>
        <origin xyz="0.0 -0.003155 0.819863" />
        <geometry>
          <box size="0.572134 0.554386 0.016" />
        </geometry>
      </collision>
      <collision>
        <origin xyz="0.0 -0.003155 -0.980943" />
        <geometry>
          <box size="0.572134 0.554386 0.016" />
        </geometry>
      </collision>
      <collision>
        <origin xyz="0.0 -0.003155 -1.05594" />
        <geometry>
          <box size="0.572134 0.554386 0.016" />
        </geometry>
      </collision>
      <collision>
        <origin xyz="0.0 0.262453 0.975825" />
        <geometry>
          <box size="0.572134 0.0209188 0.14402" />
        </geometry>
      </collision>
      <collision>
        <origin xyz="0.0 0.262453 0.857803" />
        <geometry>
          <box size="0.572134 0.0209188 0.06" />
        </geometry>
      </collision>
      <collision>
        <origin xyz="0.0 0.262453 0.857803" />
        <geometry>
          <box size="0.572134 0.0209188 0.06" />
        </geometry>
      </collision>
      <collision>
        <origin xyz="-0.20788 0.264485 -1.02629" />
        <geometry>
          <box size="0.147984 0.016 0.074692" />
        </geometry>
      </collision>
    </link>

    <joint name="fridge_base_joint" type="fixed">
      <origin xyz="0.00292496 -0.01918092 -0.0816938" rpy="0.0 0.0 0.0" />
      <parent link="cabinet3" />
      <child link="fridge_base" />
    </joint>

    <link name="fridge_base">
      <visual>
        <geometry>
          <mesh filename="package://iai_apartment/meshes/unreal/SM_Fridge_Base.dae" />
        </geometry>
      </visual>
      <collision>
        <origin xyz="0.257778 -0.016051 0.0" />
        <geometry>
          <box size="0.043244 0.483652 1.75881" />
        </geometry>
      </collision>
      <collision>
        <origin xyz="-0.257778 -0.016051 0.0" />
        <geometry>
          <box size="0.043244 0.483652 1.75881" />
        </geometry>
      </collision>
      <collision>
        <origin xyz="0.223235 0.029351 -0.561142" />
        <geometry>
          <box size="0.024554 0.392848 0.636392" />
        </geometry>
      </collision>
      <collision>
        <origin xyz="-0.223235 0.029351 -0.561142" />
        <geometry>
          <box size="0.024554 0.392848 0.636392" />
        </geometry>
      </collision>
      <collision>
        <origin xyz="0.0 -0.011034 0.855407" />
        <geometry>
          <box size="0.556434 0.49339 0.047996" />
        </geometry>
      </collision>
      <collision>
        <origin xyz="0.0 0.029351 0.839695" />
        <geometry>
          <box size="0.469566 0.392848 0.07542" />
        </geometry>
      </collision>
      <collision>
        <origin xyz="0.0 0.029351 0.224975" />
        <geometry>
          <box size="0.469566 0.392848 0.025" />
        </geometry>
      </collision>
      <collision>
        <origin xyz="0.0 0.029351 -0.18398" />
        <geometry>
          <box size="0.469566 0.392848 0.11793" />
        </geometry>
      </collision>
      <collision>
        <origin xyz="0.0 0.029351 -0.842617" />
        <geometry>
          <box size="0.469566 0.392848 0.073576" />
        </geometry>
      </collision>
      <collision>
        <origin xyz="0.0 -0.159364 0.339754" />
        <geometry>
          <box size="0.469566 0.01564 0.929316" />
        </geometry>
      </collision>
      <collision>
        <origin xyz="0.0 -0.199778 -0.524221" />
        <geometry>
          <box size="0.469566 0.116796 0.56255" />
        </geometry>
      </collision>
    </link>

    <joint name="fridge_shelf1_joint" type="fixed">
      <origin xyz="-0.00204316 -0.00102744 0.54545097" rpy="0.0 0.0 0.0" />
      <parent link="fridge_base" />
      <child link="fridge_shelf1" />
    </joint>

    <link name="fridge_shelf1">
      <visual>
        <geometry>
          <mesh filename="package://iai_apartment/meshes/unreal/SM_Fridge_Shelf.dae" />
        </geometry>
      </visual>
      <collision>
        <origin xyz="0.0 0.0 0.0" />
        <geometry>
          <box size="0.468268 0.267982 0.009088" />
        </geometry>
      </collision>
    </link>

    <joint name="fridge_shelf2_joint" type="fixed">
      <origin xyz="-0.00204316 -0.00102744 0.41123558" rpy="0.0 0.0 0.0" />
      <parent link="fridge_base" />
      <child link="fridge_shelf2" />
    </joint>

    <link name="fridge_shelf2">
      <visual>
        <geometry>
          <mesh filename="package://iai_apartment/meshes/unreal/SM_Fridge_Shelf.dae" />
        </geometry>
      </visual>
      <collision>
        <origin xyz="0.0 0.0 0.0" />
        <geometry>
          <box size="0.468268 0.267982 0.009088" />
        </geometry>
      </collision>
    </link>

    <joint name="fridge_drawer1_joint" type="prismatic">
      <origin xyz="-0.00223595 -0.01209006 0.11025719" rpy="0.0 0.0 0.0" />
      <parent link="fridge_base" />
      <child link="fridge_drawer1" />
      <axis xyz="0 1 0" />
      <limit effort="1000.0" lower="0.0" upper="0.30" velocity="0.5" />
    </joint>

    <link name="fridge_drawer1">
      <visual>
        <geometry>
          <mesh filename="package://iai_apartment/meshes/unreal/SM_Fridge_Drawer_01.dae" />
        </geometry>
      </visual>
      <collision>
        <origin xyz="0.0 0.169309 0.070506" />
        <geometry>
          <box size="0.454234 0.005 0.023842" />
        </geometry>
      </collision>
      <collision>
        <origin xyz="0.0 0.169309 -0.034598" />
        <geometry>
          <box size="0.454234 0.002896 0.095728" />
        </geometry>
      </collision>
      <collision>
        <origin xyz="0.0 -0.16468 0.0" />
        <geometry>
          <box size="0.454234 0.004246 0.164152" />
        </geometry>
      </collision>
      <collision>
        <origin xyz="-0.217307 0.0 0.0" />
        <geometry>
          <box size="0.01966 0.343522 0.164152" />
        </geometry>
      </collision>
      <collision>
        <origin xyz="0.217307 0.0 0.0" />
        <geometry>
          <box size="0.01966 0.343522 0.164152" />
        </geometry>
      </collision>
      <collision>
        <origin xyz="0.0 0.0 -0.080999" />
        <geometry>
          <box size="0.454234 0.343522 0.002744" />
        </geometry>
      </collision>
    </link>

    <joint name="fridge_drawer2_joint" type="prismatic">
      <origin xyz="0.00198811 -0.01548341 -0.0496125" rpy="0.0 0.0 0.0" />
      <parent link="fridge_base" />
      <child link="fridge_drawer2" />
      <axis xyz="0 1 0" />
      <limit effort="1000.0" lower="0.0" upper="0.30" velocity="0.5" />
    </joint>

    <link name="fridge_drawer2">
      <visual>
        <geometry>
          <mesh filename="package://iai_apartment/meshes/unreal/SM_Fridge_Drawer_02.dae" />
        </geometry>
      </visual>
      <collision>
        <origin xyz="0.0 0.169309 0.057007" />
        <geometry>
          <box size="0.454234 0.005 0.023602" />
        </geometry>
      </collision>
      <collision>
        <origin xyz="0.0 0.169309 -0.036775" />
        <geometry>
          <box size="0.454234 0.002896 0.064222" />
        </geometry>
      </collision>
      <collision>
        <origin xyz="0.0 -0.16468 0.0" />
        <geometry>
          <box size="0.454234 0.004246 0.137882" />
        </geometry>
      </collision>
      <collision>
        <origin xyz="-0.217307 0.0 0.0" />
        <geometry>
          <box size="0.01966 0.343522 0.137882" />
        </geometry>
      </collision>
      <collision>
        <origin xyz="0.217307 0.0 0.0" />
        <geometry>
          <box size="0.01966 0.343522 0.137882" />
        </geometry>
      </collision>
      <collision>
        <origin xyz="0.0 0.0 -0.066161" />
        <geometry>
          <box size="0.454234 0.343522 0.002744" />
        </geometry>
      </collision>
    </link>

    <joint name="fridge_drawer3_joint" type="prismatic">
      <origin xyz="-0.00251899 -0.03265699 -0.3561763" rpy="0.0 0.0 0.0" />
      <parent link="fridge_base" />
      <child link="fridge_drawer3" />
      <axis xyz="0 1 0" />
      <limit effort="1000.0" lower="0.0" upper="0.30" velocity="0.5" />
    </joint>

    <link name="fridge_drawer3">
      <visual>
        <geometry>
          <mesh filename="package://iai_apartment/meshes/unreal/SM_Fridge_Drawer_03.dae" />
        </geometry>
      </visual>
      <collision>
        <origin xyz="0.0 0.165482 0.083453" />
        <geometry>
          <box size="0.408956 0.002 0.024924" />
        </geometry>
      </collision>
      <collision>
        <origin xyz="0.0 0.165482 -0.037113" />
        <geometry>
          <box size="0.408956 0.002 0.11774" />
        </geometry>
      </collision>
      <collision>
        <origin xyz="0.0 -0.154928 0.0" />
        <geometry>
          <box size="0.408956 0.00311 0.19183" />
        </geometry>
      </collision>
      <collision>
        <origin xyz="-0.197083 0.004962 0.0" />
        <geometry>
          <box size="0.01464 0.32289 0.19183" />
        </geometry>
      </collision>
      <collision>
        <origin xyz="0.197083 0.004962 0.0" />
        <geometry>
          <box size="0.01464 0.32289 0.19183" />
        </geometry>
      </collision>
      <collision>
        <origin xyz="0.0 0.004962 -0.095072" />
        <geometry>
          <box size="0.408956 0.32289 0.001822" />
        </geometry>
      </collision>
    </link>

    <joint name="fridge_drawer4_joint" type="prismatic">
      <origin xyz="-0.00508168 -0.02885223 -0.53299805" rpy="0.0 0.0 0.0" />
      <parent link="fridge_base" />
      <child link="fridge_drawer4" />
      <axis xyz="0 1 0" />
      <limit effort="1000.0" lower="0.0" upper="0.30" velocity="0.5" />
    </joint>

    <link name="fridge_drawer4">
      <visual>
        <geometry>
          <mesh filename="package://iai_apartment/meshes/unreal/SM_Fridge_Drawer_04.dae" />
        </geometry>
      </visual>
      <collision>
        <origin xyz="0.0 0.165482 0.063456" />
        <geometry>
          <box size="0.408956 0.002 0.024924" />
        </geometry>
      </collision>
      <collision>
        <origin xyz="0.0 0.165482 -0.035978" />
        <geometry>
          <box size="0.408956 0.002 0.08" />
        </geometry>
      </collision>
      <collision>
        <origin xyz="0.0 -0.155483 0.0" />
        <geometry>
          <box size="0.408956 0.002 0.151834" />
        </geometry>
      </collision>
      <collision>
        <origin xyz="-0.196311 0.0 0.0" />
        <geometry>
          <box size="0.016186 0.332816 0.151834" />
        </geometry>
      </collision>
      <collision>
        <origin xyz="0.196311 0.0 0.0" />
        <geometry>
          <box size="0.016186 0.332816 0.151834" />
        </geometry>
      </collision>
      <collision>
        <origin xyz="0.0 0.0 -0.074992" />
        <geometry>
          <box size="0.408956 0.332816 0.002" />
        </geometry>
      </collision>
    </link>

    <joint name="fridge_drawer5_joint" type="prismatic">
      <origin xyz="0.0 -0.064807663 0.712787175" rpy="0.0 0.0 0.0" />
      <parent link="fridge_base" />
      <child link="fridge_drawer5" />
      <axis xyz="0 1 0" />
      <limit effort="1000.0" lower="0.0" upper="0.30" velocity="0.5" />
    </joint>

    <link name="fridge_drawer5">
      <visual>
        <geometry>
          <mesh filename="package://iai_apartment/meshes/unreal/SM_Fridge_Drawer_05.dae" />
        </geometry>
      </visual>
      <collision>
        <origin xyz="0.0 0.120488 0.08099" />
        <geometry>
          <box size="0.408808 0.002 0.024998" />
        </geometry>
      </collision>
      <collision>
        <origin xyz="0.0 0.118669 -0.03813" />
        <geometry>
          <box size="0.408808 0.002 0.110706" />
        </geometry>
      </collision>
      <collision>
        <origin xyz="0.0 -0.108269 0.0" />
        <geometry>
          <box size="0.408808 0.006434 0.151834" />
        </geometry>
      </collision>
      <collision>
        <origin xyz="-0.196942 0.0 0.0" />
        <geometry>
          <box size="0.014922 0.240842 0.151834" />
        </geometry>
      </collision>
      <collision>
        <origin xyz="0.196942 0.0 0.0" />
        <geometry>
          <box size="0.014922 0.240842 0.151834" />
        </geometry>
      </collision>
      <collision>
        <origin xyz="0.0 0.0 -0.09249" />
        <geometry>
          <box size="0.408808 0.240842 0.002" />
        </geometry>
      </collision>
    </link>

  </xacro:macro>
</robot>